Workbook

Sheet 信息汇总
A1: 总添加人数 | B1: 有效 leads 人数/占比 | C1: 转化人数/占比 | D1: 填写问卷人数/占比 | E1: 领卡人数/占比 | F1: 进群人数/占比 | G1: 交作业人数/占比 | H1: 流失人数/占比 | J1: 未回复人数/占比 | K1: 挖需人数/占比 | L1: SA 类人数/占比 | M1: 建联人数/占比 | N1: 破冰人数/占比 | O1: 挖需人数/占比 | P1: 痛点人数/占比 | Q1: 匹配产品人数/占比 | R1: 异议解决人数/占比 | S1: 关单人数/占比 | T1: S 类人数/占比 | U1: A 类人数/占比 | V1: B 类人数/占比 | W1: 不跟进人数/占比 | X1: 在期会员人数/占比 | Y1: 骗子人数/占比 | Z1: 重复添加人数 | AA1: 往期会员人数/占比 | AB1: 领过体验卡人数/占比 | AC1: 待领取体验卡人数/占比 | AD1: 延期人数/占比
A2: {=SUMPRODUCT(--(LEN(A5:A1659)>0))} | B2: =A2-H2-X2-Y2-Z2 | C2: {=SUMPRODUCT(--(TRIM(H5:H1659)="已成交"))} | D2: {=SUMPRODUCT(--(LEN(X5:X1659)>0))} | E2: {=SUMPRODUCT(--(LEN(E5:E1659)>0))} | F2: {=SUMPRODUCT(--(LEN(F5:F1659)>0))} | G2: {=SUMPRODUCT(--(LEN(O5:O1659)>0))} | H2: {=SUMPRODUCT(--(TRIM(D5:D1659)="已流失"))} | J2: {=SUMPRODUCT(--(TRIM(H5:H1659)="建联"))} | K2: =O2 | L2: =T2+U2 | M2: {=SUMPRODUCT(--(TRIM(H5:H1659)="建联"))} | N2: {=SUMPRODUCT(--(TRIM(H5:H1659)="破冰"))} | O2: {=SUMPRODUCT(--(TRIM(H5:H1659)="需求"))} | P2: {=SUMPRODUCT(--(TRIM(H5:H1659)="痛点"))} | Q2: {=SUMPRODUCT(--(TRIM(H5:H1659)="匹配产品"))} | R2: {=SUMPRODUCT(--(TRIM(H5:H1659)="异议解决"))} | S2: {=SUMPRODUCT(--(TRIM(H5:H1659)="关单"))} | T2: {=SUMPRODUCT(--(TRIM(G5:G1659)="S"))} | U2: {=SUMPRODUCT(--(TRIM(G5:G1659)="A"))} | V2: {=SUMPRODUCT(--(TRIM(G5:G1659)="B"))} | W2: {=SUMPRODUCT(--(TRIM(G5:G1659)="不跟进"))} | X2: {=SUMPRODUCT(--(TRIM(U5:U1659)="会员_7"))} | Y2: {=SUMPRODUCT(--(TRIM(G5:G1659)="诈骗"))} | Z2: =COUNTIF(B5:B1659, "*重复*") | AA2: {=SUMPRODUCT(--(TRIM(U5:U1659)="会员_往期未续费"))} | AB2: {=SUMPRODUCT(--(TRIM(U5:U1659)="体验卡"))} | AC2: =B2-AA2-AB2 | AD2: {=SUMPRODUCT(--(TRIM(G5:G1659)="延期"))}
B3: =B2/A2 | C3: =C2/B2 | D3: =D2/B2 | E3: =E2/B2 | F3: =F2/B2 | G3: =G2/B2 | H3: =H2/A2 | J3: =J2/A2 | K3: =K2/B2+P3+Q3+R3+S3 | L3: =L2/B2 | M3: =M2/A2 | N3: =N2/B2+O3+P3+Q3+R3+S3 | O3: =O2/B2+P3+Q3+R3+S3 | P3: =P2/B2+Q3+R3+S3 | Q3: =Q2/B2+R3+S3 | R3: =R2/B2+S3 | S3: =S2/B2 | T3: =T2/B2 | U3: =U2/B2 | V3: =V2/A2 | W3: =W2/B2 | X3: =X2/A2 | Y3: =Y2/A2 | Z3: =Z2/A2 | AA3: =AA2/A2 | AB3: =AB2/A2 | AC3: =AC2/B2 | AD3: =AD2/B2
B4: 企微备注名 | C4: 所在账号 | D4: 是否流失 | E4: 是否领卡 | F4: 是否进群 | G4: 用户属性 | H4: 用户阶段 | J4: 用户备注 | K4: 用户基本信息 | L4: 第一课在线时长 | M4: 第一课回放时长 | N4: 第二课在线时长 | O4: 直播听后感 | P4: 作业 1 | Q4: 作业 2 | R4: 作业 3 | S4: 企业标签 | T4: 性别 | U4: 往期身份 | V4: 收货地址 | W4: 收件人 | X4: 您所在的城市为 | Y4: 您现在的工作是 | Z4: 您的工作年限是 | AA4: 工作或项目年收入 | AB4: 您目前所处的赚钱阶段 | AC4: 之前是否有做过项目的经历（如果有，可以简单说一下自己做过的项目~） | AD4: 从那些渠道了解的生财 | AE4: 请问来生财有术，主要是想解决赚钱路上那些方面的问题？我把相关资料发给你 | AF4: 是否进群 | AG4: IP 课 | AH4: 小报童 | AI4: 365问 | AJ4: 礼品卡 | AK4: 返差价 | AL4: 兑换话术 | AM4: 差价话术 | AN4: 星球编号 | AO4: 交付结束
A5: =IF('微伴数据'!A2="","",'微伴数据'!A2) | B5: =IF('微伴数据'!B2="","",'微伴数据'!B2) | C5: =IF('微伴数据'!G2="","",'微伴数据'!G2) | D5: =IF('微伴数据'!D2="","",'微伴数据'!D2) | E5: =IF('微伴数据'!CR2="","",'微伴数据'!CR2) | F5: =IF('微伴数据'!CL2="","",'微伴数据'!CL2) | G5: S | H5: 已成交 | I5: =VLOOKUP(A5,'Sheet9'!A:A,1,0) | K5: =T5&CHAR(10)&U5&CHAR(10)&V5&CHAR(10)&Y5&CHAR(10)&Z5&CHAR(10)&AA5&CHAR(10)&AB5&CHAR(10)&AC5&CHAR(10)&AD5&CHAR(10)&AE5 | L5: =IFERROR(VLOOKUP(#REF!,'第一课直播'!D:L,9,0),IFERROR(VLOOKUP('第一课回放'!C:H,5,0),"未到课")) | M5: =IFERROR(VLOOKUP(#REF!,'第一课回放'!C:H,5,0),"0:00:00") | N5: =IFERROR(VLOOKUP(#REF!,'第二课直播'!D:L,9,0),"未到课") | S5: =IFERROR(VLOOKUP(A5,'微伴数据'!A:DB,12,0),"") | T5: =IFERROR(VLOOKUP(A5,'微伴数据'!A:DB,32,0),"") | U5: =IFERROR(VLOOKUP(A5,'微伴数据'!A:DC,81,0),"") | V5: =IFERROR(VLOOKUP(#REF!,'星橙地址'!A:V,9,0),"") | W5: =IFERROR(VLOOKUP(#REF!,'星橙地址'!A:V,10,0),"") | X5: =IFERROR(VLOOKUP(A5,'星云问卷'!A:O,8,0),"") | Y5: =IFERROR(VLOOKUP(A5,'星云问卷'!A:O,9,0),"") | Z5: =IFERROR(VLOOKUP(A5,'星云问卷'!A:O,10,0),"") | AA5: =IFERROR(VLOOKUP(A5,'星云问卷'!A:O,11,0),"") | AB5: =IFERROR(VLOOKUP(A5,'星云问卷'!A:O,12,0),"") | AC5: =IFERROR(VLOOKUP(A5,'星云问卷'!A:O,13,0),"") | AD5: =IFERROR(VLOOKUP(A5,'星云问卷'!A:O,14,0),"") | AE5: =IFERROR(VLOOKUP(A5,'星云问卷'!A:O,15,0),"") | AF5: =IFERROR(VLOOKUP(A5,'微伴数据'!A:DB,72,0),"") | AG5: 54DCsd5b | AH5: https://xiaobot.net/invitation/ae6b3-8be22-0a6d1-870e1 | AI5: 6dvE2Dzy | AL5: =CONCATENATE( " 我把体验营用户专属福利给你发一下哈：" & CHAR(10) & CHAR(10), "1.《抖音商业IP课》" & CHAR(10), "兑换码：", AG5, CHAR(10), "兑换码使用地址：https://appamvpb5mq9834.h5.xiaoeknow.com/p/t/v1/ecommerce/mkt/redeem_index" & CHAR(10) & CHAR(10), "2.《生财有术66个项目精选》" & CHAR(10), "兑换码：", AH5, CHAR(10), "使用方式：微信搜索小报童投递-点击开始阅读-点击生财有术项目精选即可" & CHAR(10) & CHAR(10), "3.《生财365问》" & CHAR(10), "兑换码：", AI5, CHAR(10), "使用方式：https://appamvpb5mq9834.h5.xiaoeknow.com/p/t/v1/ecommerce/mkt/redeem_index")
A6: =IF('微伴数据'!A3="","",'微伴数据'!A3) | B6: =IF('微伴数据'!B3="","",'微伴数据'!B3) | C6: =IF('微伴数据'!G3="","",'微伴数据'!G3) | D6: =IF('微伴数据'!D3="","",'微伴数据'!D3) | E6: =IF('微伴数据'!CR3="","",'微伴数据'!CR3) | F6: =IF('微伴数据'!CL3="","",'微伴数据'!CL3) | G6: B | H6: 建联 | I6: =VLOOKUP(A6,'Sheet9'!A:A,1,0) | K6: =T6&CHAR(10)&U6&CHAR(10)&V6&CHAR(10)&Y6&CHAR(10)&Z6&CHAR(10)&AA6&CHAR(10)&AB6&CHAR(10)&AC6&CHAR(10)&AD6&CHAR(10)&AE6 | L6: =IFERROR(VLOOKUP(#REF!,'第一课直播'!D:L,9,0),IFERROR(VLOOKUP('第一课回放'!C:H,5,0),"未到课")) | M6: =IFERROR(VLOOKUP(#REF!,'第一课回放'!C:H,5,0),"0:00:00") | N6: =IFERROR(VLOOKUP(#REF!,'第二课直播'!D:L,9,0),"未到课") | S6: =IFERROR(VLOOKUP(A6,'微伴数据'!A:DB,12,0),"") | T6: =IFERROR(VLOOKUP(A6,'微伴数据'!A:DB,32,0),"") | U6: =IFERROR(VLOOKUP(A6,'微伴数据'!A:DC,81,0),"") | V6: =IFERROR(VLOOKUP(#REF!,'星橙地址'!A:V,9,0),"") | W6: =IFERROR(VLOOKUP(#REF!,'星橙地址'!A:V,10,0),"") | X6: =IFERROR(VLOOKUP(A6,'星云问卷'!A:O,8,0),"") | Y6: =IFERROR(VLOOKUP(A6,'星云问卷'!A:O,9,0),"") | Z6: =IFERROR(VLOOKUP(A6,'星云问卷'!A:O,10,0),"") | AA6: =IFERROR(VLOOKUP(A6,'星云问卷'!A:O,11,0),"") | AB6: =IFERROR(VLOOKUP(A6,'星云问卷'!A:O,12,0),"") | AC6: =IFERROR(VLOOKUP(A6,'星云问卷'!A:O,13,0),"") | AD6: =IFERROR(VLOOKUP(A6,'星云问卷'!A:O,14,0),"") | AE6: =IFERROR(VLOOKUP(A6,'星云问卷'!A:O,15,0),"") | AF6: =IFERROR(VLOOKUP(A6,'微伴数据'!A:DB,72,0),"") | AL6: =CONCATENATE( " 我把体验营用户专属福利给你发一下哈：" & CHAR(10) & CHAR(10), "1.《抖音商业IP课》" & CHAR(10), "兑换码：", AG6, CHAR(10), "兑换码使用地址：https://appamvpb5mq9834.h5.xiaoeknow.com/p/t/v1/ecommerce/mkt/redeem_index" & CHAR(10) & CHAR(10), "2.《生财有术66个项目精选》" & CHAR(10), "兑换码：", AH6, CHAR(10), "使用方式：微信搜索小报童投递-点击开始阅读-点击生财有术项目精选即可" & CHAR(10) & CHAR(10), "3.《生财365问》" & CHAR(10), "兑换码：", AI6, CHAR(10), "使用方式：https://appamvpb5mq9834.h5.xiaoeknow.com/p/t/v1/ecommerce/mkt/redeem_index")
A7: =IF('微伴数据'!A4="","",'微伴数据'!A4) | B7: =IF('微伴数据'!B4="","",'微伴数据'!B4) | C7: =IF('微伴数据'!G4="","",'微伴数据'!G4) | D7: =IF('微伴数据'!D4="","",'微伴数据'!D4) | E7: =IF('微伴数据'!CR4="","",'微伴数据'!CR4) | F7: =IF('微伴数据'!CL4="","",'微伴数据'!CL4) | G7: B | H7: 建联 | I7: =VLOOKUP(A7,'Sheet9'!A:A,1,0) | K7: =T7&CHAR(10)&U7&CHAR(10)&V7&CHAR(10)&Y7&CHAR(10)&Z7&CHAR(10)&AA7&CHAR(10)&AB7&CHAR(10)&AC7&CHAR(10)&AD7&CHAR(10)&AE7 | L7: =IFERROR(VLOOKUP(#REF!,'第一课直播'!D:L,9,0),IFERROR(VLOOKUP('第一课回放'!C:H,5,0),"未到课")) | M7: =IFERROR(VLOOKUP(#REF!,'第一课回放'!C:H,5,0),"0:00:00") | N7: =IFERROR(VLOOKUP(#REF!,'第二课直播'!D:L,9,0),"未到课") | S7: =IFERROR(VLOOKUP(A7,'微伴数据'!A:DB,12,0),"") | T7: =IFERROR(VLOOKUP(A7,'微伴数据'!A:DB,32,0),"") | U7: =IFERROR(VLOOKUP(A7,'微伴数据'!A:DC,81,0),"") | V7: =IFERROR(VLOOKUP(#REF!,'星橙地址'!A:V,9,0),"") | W7: =IFERROR(VLOOKUP(#REF!,'星橙地址'!A:V,10,0),"") | X7: =IFERROR(VLOOKUP(A7,'星云问卷'!A:O,8,0),"") | Y7: =IFERROR(VLOOKUP(A7,'星云问卷'!A:O,9,0),"") | Z7: =IFERROR(VLOOKUP(A7,'星云问卷'!A:O,10,0),"") | AA7: =IFERROR(VLOOKUP(A7,'星云问卷'!A:O,11,0),"") | AB7: =IFERROR(VLOOKUP(A7,'星云问卷'!A:O,12,0),"") | AC7: =IFERROR(VLOOKUP(A7,'星云问卷'!A:O,13,0),"") | AD7: =IFERROR(VLOOKUP(A7,'星云问卷'!A:O,14,0),"") | AE7: =IFERROR(VLOOKUP(A7,'星云问卷'!A:O,15,0),"") | AF7: =IFERROR(VLOOKUP(A7,'微伴数据'!A:DB,72,0),"") | AL7: =CONCATENATE( " 我把体验营用户专属福利给你发一下哈：" & CHAR(10) & CHAR(10), "1.《抖音商业IP课》" & CHAR(10), "兑换码：", AG7, CHAR(10), "兑换码使用地址：https://appamvpb5mq9834.h5.xiaoeknow.com/p/t/v1/ecommerce/mkt/redeem_index" & CHAR(10) & CHAR(10), "2.《生财有术66个项目精选》" & CHAR(10), "兑换码：", AH7, CHAR(10), "使用方式：微信搜索小报童投递-点击开始阅读-点击生财有术项目精选即可" & CHAR(10) & CHAR(10), "3.《生财365问》" & CHAR(10), "兑换码：", AI7, CHAR(10), "使用方式：https://appamvpb5mq9834.h5.xiaoeknow.com/p/t/v1/ecommerce/mkt/redeem_index")
A8: =IF('微伴数据'!A5="","",'微伴数据'!A5) | B8: =IF('微伴数据'!B5="","",'微伴数据'!B5) | C8: =IF('微伴数据'!G5="","",'微伴数据'!G5) | D8: =IF('微伴数据'!D5="","",'微伴数据'!D5) | E8: =IF('微伴数据'!CR5="","",'微伴数据'!CR5) | F8: =IF('微伴数据'!CL5="","",'微伴数据'!CL5) | G8: B | H8: 建联 | I8: =VLOOKUP(A8,'Sheet9'!A:A,1,0) | K8: =T8&CHAR(10)&U8&CHAR(10)&V8&CHAR(10)&Y8&CHAR(10)&Z8&CHAR(10)&AA8&CHAR(10)&AB8&CHAR(10)&AC8&CHAR(10)&AD8&CHAR(10)&AE8 | L8: =IFERROR(VLOOKUP(#REF!,'第一课直播'!D:L,9,0),IFERROR(VLOOKUP('第一课回放'!C:H,5,0),"未到课")) | M8: =IFERROR(VLOOKUP(#REF!,'第一课回放'!C:H,5,0),"0:00:00") | N8: =IFERROR(VLOOKUP(#REF!,'第二课直播'!D:L,9,0),"未到课") | S8: =IFERROR(VLOOKUP(A8,'微伴数据'!A:DB,12,0),"") | T8: =IFERROR(VLOOKUP(A8,'微伴数据'!A:DB,32,0),"") | U8: =IFERROR(VLOOKUP(A8,'微伴数据'!A:DC,81,0),"") | V8: =IFERROR(VLOOKUP(#REF!,'星橙地址'!A:V,9,0),"") | W8: =IFERROR(VLOOKUP(#REF!,'星橙地址'!A:V,10,0),"") | X8: =IFERROR(VLOOKUP(A8,'星云问卷'!A:O,8,0),"") | Y8: =IFERROR(VLOOKUP(A8,'星云问卷'!A:O,9,0),"") | Z8: =IFERROR(VLOOKUP(A8,'星云问卷'!A:O,10,0),"") | AA8: =IFERROR(VLOOKUP(A8,'星云问卷'!A:O,11,0),"") | AB8: =IFERROR(VLOOKUP(A8,'星云问卷'!A:O,12,0),"") | AC8: =IFERROR(VLOOKUP(A8,'星云问卷'!A:O,13,0),"") | AD8: =IFERROR(VLOOKUP(A8,'星云问卷'!A:O,14,0),"") | AE8: =IFERROR(VLOOKUP(A8,'星云问卷'!A:O,15,0),"") | AF8: =IFERROR(VLOOKUP(A8,'微伴数据'!A:DB,72,0),"") | AL8: =CONCATENATE( " 我把体验营用户专属福利给你发一下哈：" & CHAR(10) & CHAR(10), "1.《抖音商业IP课》" & CHAR(10), "兑换码：", AG8, CHAR(10), "兑换码使用地址：https://appamvpb5mq9834.h5.xiaoeknow.com/p/t/v1/ecommerce/mkt/redeem_index" & CHAR(10) & CHAR(10), "2.《生财有术66个项目精选》" & CHAR(10), "兑换码：", AH8, CHAR(10), "使用方式：微信搜索小报童投递-点击开始阅读-点击生财有术项目精选即可" & CHAR(10) & CHAR(10), "3.《生财365问》" & CHAR(10), "兑换码：", AI8, CHAR(10), "使用方式：https://appamvpb5mq9834.h5.xiaoeknow.com/p/t/v1/ecommerce/mkt/redeem_index")
A9: =IF('微伴数据'!A6="","",'微伴数据'!A6) | B9: =IF('微伴数据'!B6="","",'微伴数据'!B6) | C9: =IF('微伴数据'!G6="","",'微伴数据'!G6) | D9: =IF('微伴数据'!D6="","",'微伴数据'!D6) | E9: =IF('微伴数据'!CR6="","",'微伴数据'!CR6) | F9: =IF('微伴数据'!CL6="","",'微伴数据'!CL6) | G9: B | H9: 建联 | I9: =VLOOKUP(A9,'Sheet9'!A:A,1,0) | K9: =T9&CHAR(10)&U9&CHAR(10)&V9&CHAR(10)&Y9&CHAR(10)&Z9&CHAR(10)&AA9&CHAR(10)&AB9&CHAR(10)&AC9&CHAR(10)&AD9&CHAR(10)&AE9 | L9: =IFERROR(VLOOKUP(#REF!,'第一课直播'!D:L,9,0),IFERROR(VLOOKUP('第一课回放'!C:H,5,0),"未到课")) | M9: =IFERROR(VLOOKUP(#REF!,'第一课回放'!C:H,5,0),"0:00:00") | N9: =IFERROR(VLOOKUP(#REF!,'第二课直播'!D:L,9,0),"未到课") | S9: =IFERROR(VLOOKUP(A9,'微伴数据'!A:DB,12,0),"") | T9: =IFERROR(VLOOKUP(A9,'微伴数据'!A:DB,32,0),"") | U9: =IFERROR(VLOOKUP(A9,'微伴数据'!A:DC,81,0),"") | V9: =IFERROR(VLOOKUP(#REF!,'星橙地址'!A:V,9,0),"") | W9: =IFERROR(VLOOKUP(#REF!,'星橙地址'!A:V,10,0),"") | X9: =IFERROR(VLOOKUP(A9,'星云问卷'!A:O,8,0),"") | Y9: =IFERROR(VLOOKUP(A9,'星云问卷'!A:O,9,0),"") | Z9: =IFERROR(VLOOKUP(A9,'星云问卷'!A:O,10,0),"") | AA9: =IFERROR(VLOOKUP(A9,'星云问卷'!A:O,11,0),"") | AB9: =IFERROR(VLOOKUP(A9,'星云问卷'!A:O,12,0),"") | AC9: =IFERROR(VLOOKUP(A9,'星云问卷'!A:O,13,0),"") | AD9: =IFERROR(VLOOKUP(A9,'星云问卷'!A:O,14,0),"") | AE9: =IFERROR(VLOOKUP(A9,'星云问卷'!A:O,15,0),"") | AF9: =IFERROR(VLOOKUP(A9,'微伴数据'!A:DB,72,0),"") | AL9: =CONCATENATE( " 我把体验营用户专属福利给你发一下哈：" & CHAR(10) & CHAR(10), "1.《抖音商业IP课》" & CHAR(10), "兑换码：", AG9, CHAR(10), "兑换码使用地址：https://appamvpb5mq9834.h5.xiaoeknow.com/p/t/v1/ecommerce/mkt/redeem_index" & CHAR(10) & CHAR(10), "2.《生财有术66个项目精选》" & CHAR(10), "兑换码：", AH9, CHAR(10), "使用方式：微信搜索小报童投递-点击开始阅读-点击生财有术项目精选即可" & CHAR(10) & CHAR(10), "3.《生财365问》" & CHAR(10), "兑换码：", AI9, CHAR(10), "使用方式：https://appamvpb5mq9834.h5.xiaoeknow.com/p/t/v1/ecommerce/mkt/redeem_index")
A10: =IF('微伴数据'!A7="","",'微伴数据'!A7) | B10: =IF('微伴数据'!B7="","",'微伴数据'!B7) | C10: =IF('微伴数据'!G7="","",'微伴数据'!G7) | D10: =IF('微伴数据'!D7="","",'微伴数据'!D7) | E10: =IF('微伴数据'!CR7="","",'微伴数据'!CR7) | F10: =IF('微伴数据'!CL7="","",'微伴数据'!CL7) | G10: B | H10: 建联 | I10: =VLOOKUP(A10,'Sheet9'!A:A,1,0) | K10: =T10&CHAR(10)&U10&CHAR(10)&V10&CHAR(10)&Y10&CHAR(10)&Z10&CHAR(10)&AA10&CHAR(10)&AB10&CHAR(10)&AC10&CHAR(10)&AD10&CHAR(10)&AE10 | L10: =IFERROR(VLOOKUP(#REF!,'第一课直播'!D:L,9,0),IFERROR(VLOOKUP('第一课回放'!C:H,5,0),"未到课")) | M10: =IFERROR(VLOOKUP(#REF!,'第一课回放'!C:H,5,0),"0:00:00") | N10: =IFERROR(VLOOKUP(#REF!,'第二课直播'!D:L,9,0),"未到课") | S10: =IFERROR(VLOOKUP(A10,'微伴数据'!A:DB,12,0),"") | T10: =IFERROR(VLOOKUP(A10,'微伴数据'!A:DB,32,0),"") | U10: =IFERROR(VLOOKUP(A10,'微伴数据'!A:DC,81,0),"") | V10: =IFERROR(VLOOKUP(#REF!,'星橙地址'!A:V,9,0),"") | W10: =IFERROR(VLOOKUP(#REF!,'星橙地址'!A:V,10,0),"") | X10: =IFERROR(VLOOKUP(A10,'星云问卷'!A:O,8,0),"") | Y10: =IFERROR(VLOOKUP(A10,'星云问卷'!A:O,9,0),"") | Z10: =IFERROR(VLOOKUP(A10,'星云问卷'!A:O,10,0),"") | AA10: =IFERROR(VLOOKUP(A10,'星云问卷'!A:O,11,0),"") | AB10: =IFERROR(VLOOKUP(A10,'星云问卷'!A:O,12,0),"") | AC10: =IFERROR(VLOOKUP(A10,'星云问卷'!A:O,13,0),"") | AD10: =IFERROR(VLOOKUP(A10,'星云问卷'!A:O,14,0),"") | AE10: =IFERROR(VLOOKUP(A10,'星云问卷'!A:O,15,0),"") | AF10: =IFERROR(VLOOKUP(A10,'微伴数据'!A:DB,72,0),"") | AL10: =CONCATENATE( " 我把体验营用户专属福利给你发一下哈：" & CHAR(10) & CHAR(10), "1.《抖音商业IP课》" & CHAR(10), "兑换码：", AG10, CHAR(10), "兑换码使用地址：https://appamvpb5mq9834.h5.xiaoeknow.com/p/t/v1/ecommerce/mkt/redeem_index" & CHAR(10) & CHAR(10), "2.《生财有术66个项目精选》" & CHAR(10), "兑换码：", AH10, CHAR(10), "使用方式：微信搜索小报童投递-点击开始阅读-点击生财有术项目精选即可" & CHAR(10) & CHAR(10), "3.《生财365问》" & CHAR(10), "兑换码：", AI10, CHAR(10), "使用方式：https://appamvpb5mq9834.h5.xiaoeknow.com/p/t/v1/ecommerce/mkt/redeem_index")
A11: =IF('微伴数据'!A8="","",'微伴数据'!A8) | B11: =IF('微伴数据'!B8="","",'微伴数据'!B8) | C11: =IF('微伴数据'!G8="","",'微伴数据'!G8) | D11: =IF('微伴数据'!D8="","",'微伴数据'!D8) | E11: =IF('微伴数据'!CR8="","",'微伴数据'!CR8) | F11: =IF('微伴数据'!CL8="","",'微伴数据'!CL8) | G11: A | H11: 建联 | I11: =VLOOKUP(A11,'Sheet9'!A:A,1,0) | K11: =T11&CHAR(10)&U11&CHAR(10)&V11&CHAR(10)&Y11&CHAR(10)&Z11&CHAR(10)&AA11&CHAR(10)&AB11&CHAR(10)&AC11&CHAR(10)&AD11&CHAR(10)&AE11 | L11: =IFERROR(VLOOKUP(#REF!,'第一课直播'!D:L,9,0),IFERROR(VLOOKUP('第一课回放'!C:H,5,0),"未到课")) | M11: =IFERROR(VLOOKUP(#REF!,'第一课回放'!C:H,5,0),"0:00:00") | N11: =IFERROR(VLOOKUP(#REF!,'第二课直播'!D:L,9,0),"未到课") | S11: =IFERROR(VLOOKUP(A11,'微伴数据'!A:DB,12,0),"") | T11: =IFERROR(VLOOKUP(A11,'微伴数据'!A:DB,32,0),"") | U11: =IFERROR(VLOOKUP(A11,'微伴数据'!A:DC,81,0),"") | V11: =IFERROR(VLOOKUP(#REF!,'星橙地址'!A:V,9,0),"") | W11: =IFERROR(VLOOKUP(#REF!,'星橙地址'!A:V,10,0),"") | X11: =IFERROR(VLOOKUP(A11,'星云问卷'!A:O,8,0),"") | Y11: =IFERROR(VLOOKUP(A11,'星云问卷'!A:O,9,0),"") | Z11: =IFERROR(VLOOKUP(A11,'星云问卷'!A:O,10,0),"") | AA11: =IFERROR(VLOOKUP(A11,'星云问卷'!A:O,11,0),"") | AB11: =IFERROR(VLOOKUP(A11,'星云问卷'!A:O,12,0),"") | AC11: =IFERROR(VLOOKUP(A11,'星云问卷'!A:O,13,0),"") | AD11: =IFERROR(VLOOKUP(A11,'星云问卷'!A:O,14,0),"") | AE11: =IFERROR(VLOOKUP(A11,'星云问卷'!A:O,15,0),"") | AF11: =IFERROR(VLOOKUP(A11,'微伴数据'!A:DB,72,0),"") | AG11: 54BDGUcu | AH11: https://xiaobot.net/invitation/775fa-59965-f0225-3dbc4/ | AI11: 6drKTMfv | AL11: =CONCATENATE( " 我把体验营用户专属福利给你发一下哈：" & CHAR(10) & CHAR(10), "1.《抖音商业IP课》" & CHAR(10), "兑换码：", AG11, CHAR(10), "兑换码使用地址：https://appamvpb5mq9834.h5.xiaoeknow.com/p/t/v1/ecommerce/mkt/redeem_index" & CHAR(10) & CHAR(10), "2.《生财有术66个项目精选》" & CHAR(10), "兑换码：", AH11, CHAR(10), "使用方式：微信搜索小报童投递-点击开始阅读-点击生财有术项目精选即可" & CHAR(10) & CHAR(10), "3.《生财365问》" & CHAR(10), "兑换码：", AI11, CHAR(10), "使用方式：https://appamvpb5mq9834.h5.xiaoeknow.com/p/t/v1/ecommerce/mkt/redeem_index") | AO11: 纳入用户画像
A12: =IF('微伴数据'!A9="","",'微伴数据'!A9) | B12: =IF('微伴数据'!B9="","",'微伴数据'!B9) | C12: =IF('微伴数据'!G9="","",'微伴数据'!G9) | D12: =IF('微伴数据'!D9="","",'微伴数据'!D9) | E12: =IF('微伴数据'!CR9="","",'微伴数据'!CR9) | F12: =IF('微伴数据'!CL9="","",'微伴数据'!CL9) | G12: A | H12: 建联 | I12: =VLOOKUP(A12,'Sheet9'!A:A,1,0) | K12: =T12&CHAR(10)&U12&CHAR(10)&V12&CHAR(10)&Y12&CHAR(10)&Z12&CHAR(10)&AA12&CHAR(10)&AB12&CHAR(10)&AC12&CHAR(10)&AD12&CHAR(10)&AE12 | L12: =IFERROR(VLOOKUP(#REF!,'第一课直播'!D:L,9,0),IFERROR(VLOOKUP('第一课回放'!C:H,5,0),"未到课")) | M12: =IFERROR(VLOOKUP(#REF!,'第一课回放'!C:H,5,0),"0:00:00") | N12: =IFERROR(VLOOKUP(#REF!,'第二课直播'!D:L,9,0),"未到课") | S12: =IFERROR(VLOOKUP(A12,'微伴数据'!A:DB,12,0),"") | T12: =IFERROR(VLOOKUP(A12,'微伴数据'!A:DB,32,0),"") | U12: =IFERROR(VLOOKUP(A12,'微伴数据'!A:DC,81,0),"") | V12: =IFERROR(VLOOKUP(#REF!,'星橙地址'!A:V,9,0),"") | W12: =IFERROR(VLOOKUP(#REF!,'星橙地址'!A:V,10,0),"") | X12: =IFERROR(VLOOKUP(A12,'星云问卷'!A:O,8,0),"") | Y12: =IFERROR(VLOOKUP(A12,'星云问卷'!A:O,9,0),"") | Z12: =IFERROR(VLOOKUP(A12,'星云问卷'!A:O,10,0),"") | AA12: =IFERROR(VLOOKUP(A12,'星云问卷'!A:O,11,0),"") | AB12: =IFERROR(VLOOKUP(A12,'星云问卷'!A:O,12,0),"") | AC12: =IFERROR(VLOOKUP(A12,'星云问卷'!A:O,13,0),"") | AD12: =IFERROR(VLOOKUP(A12,'星云问卷'!A:O,14,0),"") | AE12: =IFERROR(VLOOKUP(A12,'星云问卷'!A:O,15,0),"") | AF12: =IFERROR(VLOOKUP(A12,'微伴数据'!A:DB,72,0),"") | AL12: =CONCATENATE( " 我把体验营用户专属福利给你发一下哈：" & CHAR(10) & CHAR(10), "1.《抖音商业IP课》" & CHAR(10), "兑换码：", AG12, CHAR(10), "兑换码使用地址：https://appamvpb5mq9834.h5.xiaoeknow.com/p/t/v1/ecommerce/mkt/redeem_index" & CHAR(10) & CHAR(10), "2.《生财有术66个项目精选》" & CHAR(10), "兑换码：", AH12, CHAR(10), "使用方式：微信搜索小报童投递-点击开始阅读-点击生财有术项目精选即可" & CHAR(10) & CHAR(10), "3.《生财365问》" & CHAR(10), "兑换码：", AI12, CHAR(10), "使用方式：https://appamvpb5mq9834.h5.xiaoeknow.com/p/t/v1/ecommerce/mkt/redeem_index")
A13: =IF('微伴数据'!A10="","",'微伴数据'!A10) | B13: =IF('微伴数据'!B10="","",'微伴数据'!B10) | C13: =IF('微伴数据'!G10="","",'微伴数据'!G10) | D13: =IF('微伴数据'!D10="","",'微伴数据'!D10) | E13: =IF('微伴数据'!CR10="","",'微伴数据'!CR10) | F13: =IF('微伴数据'!CL10="","",'微伴数据'!CL10) | G13: B | H13: 已成交 | I13: =VLOOKUP(A13,'Sheet9'!A:A,1,0) | K13: =T13&CHAR(10)&U13&CHAR(10)&V13&CHAR(10)&Y13&CHAR(10)&Z13&CHAR(10)&AA13&CHAR(10)&AB13&CHAR(10)&AC13&CHAR(10)&AD13&CHAR(10)&AE13 | L13: =IFERROR(VLOOKUP(#REF!,'第一课直播'!D:L,9,0),IFERROR(VLOOKUP('第一课回放'!C:H,5,0),"未到课")) | M13: =IFERROR(VLOOKUP(#REF!,'第一课回放'!C:H,5,0),"0:00:00") | N13: =IFERROR(VLOOKUP(#REF!,'第二课直播'!D:L,9,0),"未到课") | S13: =IFERROR(VLOOKUP(A13,'微伴数据'!A:DB,12,0),"") | T13: =IFERROR(VLOOKUP(A13,'微伴数据'!A:DB,32,0),"") | U13: =IFERROR(VLOOKUP(A13,'微伴数据'!A:DC,81,0),"") | V13: =IFERROR(VLOOKUP(#REF!,'星橙地址'!A:V,9,0),"") | W13: =IFERROR(VLOOKUP(#REF!,'星橙地址'!A:V,10,0),"") | X13: =IFERROR(VLOOKUP(A13,'星云问卷'!A:O,8,0),"") | Y13: =IFERROR(VLOOKUP(A13,'星云问卷'!A:O,9,0),"") | Z13: =IFERROR(VLOOKUP(A13,'星云问卷'!A:O,10,0),"") | AA13: =IFERROR(VLOOKUP(A13,'星云问卷'!A:O,11,0),"") | AB13: =IFERROR(VLOOKUP(A13,'星云问卷'!A:O,12,0),"") | AC13: =IFERROR(VLOOKUP(A13,'星云问卷'!A:O,13,0),"") | AD13: =IFERROR(VLOOKUP(A13,'星云问卷'!A:O,14,0),"") | AE13: =IFERROR(VLOOKUP(A13,'星云问卷'!A:O,15,0),"") | AF13: =IFERROR(VLOOKUP(A13,'微伴数据'!A:DB,72,0),"") | AL13: =CONCATENATE( " 我把体验营用户专属福利给你发一下哈：" & CHAR(10) & CHAR(10), "1.《抖音商业IP课》" & CHAR(10), "兑换码：", AG13, CHAR(10), "兑换码使用地址：https://appamvpb5mq9834.h5.xiaoeknow.com/p/t/v1/ecommerce/mkt/redeem_index" & CHAR(10) & CHAR(10), "2.《生财有术66个项目精选》" & CHAR(10), "兑换码：", AH13, CHAR(10), "使用方式：微信搜索小报童投递-点击开始阅读-点击生财有术项目精选即可" & CHAR(10) & CHAR(10), "3.《生财365问》" & CHAR(10), "兑换码：", AI13, CHAR(10), "使用方式：https://appamvpb5mq9834.h5.xiaoeknow.com/p/t/v1/ecommerce/mkt/redeem_index") | AO13: 纳入用户画像
A14: =IF('微伴数据'!A11="","",'微伴数据'!A11) | B14: =IF('微伴数据'!B11="","",'微伴数据'!B11) | C14: =IF('微伴数据'!G11="","",'微伴数据'!G11) | D14: =IF('微伴数据'!D11="","",'微伴数据'!D11) | E14: =IF('微伴数据'!CR11="","",'微伴数据'!CR11) | F14: =IF('微伴数据'!CL11="","",'微伴数据'!CL11) | G14: B | H14: 建联 | I14: =VLOOKUP(A14,'Sheet9'!A:A,1,0) | K14: =T14&CHAR(10)&U14&CHAR(10)&V14&CHAR(10)&Y14&CHAR(10)&Z14&CHAR(10)&AA14&CHAR(10)&AB14&CHAR(10)&AC14&CHAR(10)&AD14&CHAR(10)&AE14 | L14: =IFERROR(VLOOKUP(#REF!,'第一课直播'!D:L,9,0),IFERROR(VLOOKUP('第一课回放'!C:H,5,0),"未到课")) | M14: =IFERROR(VLOOKUP(#REF!,'第一课回放'!C:H,5,0),"0:00:00") | N14: =IFERROR(VLOOKUP(#REF!,'第二课直播'!D:L,9,0),"未到课") | S14: =IFERROR(VLOOKUP(A14,'微伴数据'!A:DB,12,0),"") | T14: =IFERROR(VLOOKUP(A14,'微伴数据'!A:DB,32,0),"") | U14: =IFERROR(VLOOKUP(A14,'微伴数据'!A:DC,81,0),"") | V14: =IFERROR(VLOOKUP(#REF!,'星橙地址'!A:V,9,0),"") | W14: =IFERROR(VLOOKUP(#REF!,'星橙地址'!A:V,10,0),"") | X14: =IFERROR(VLOOKUP(A14,'星云问卷'!A:O,8,0),"") | Y14: =IFERROR(VLOOKUP(A14,'星云问卷'!A:O,9,0),"") | Z14: =IFERROR(VLOOKUP(A14,'星云问卷'!A:O,10,0),"") | AA14: =IFERROR(VLOOKUP(A14,'星云问卷'!A:O,11,0),"") | AB14: =IFERROR(VLOOKUP(A14,'星云问卷'!A:O,12,0),"") | AC14: =IFERROR(VLOOKUP(A14,'星云问卷'!A:O,13,0),"") | AD14: =IFERROR(VLOOKUP(A14,'星云问卷'!A:O,14,0),"") | AE14: =IFERROR(VLOOKUP(A14,'星云问卷'!A:O,15,0),"") | AF14: =IFERROR(VLOOKUP(A14,'微伴数据'!A:DB,72,0),"") | AL14: =CONCATENATE( " 我把体验营用户专属福利给你发一下哈：" & CHAR(10) & CHAR(10), "1.《抖音商业IP课》" & CHAR(10), "兑换码：", AG14, CHAR(10), "兑换码使用地址：https://appamvpb5mq9834.h5.xiaoeknow.com/p/t/v1/ecommerce/mkt/redeem_index" & CHAR(10) & CHAR(10), "2.《生财有术66个项目精选》" & CHAR(10), "兑换码：", AH14, CHAR(10), "使用方式：微信搜索小报童投递-点击开始阅读-点击生财有术项目精选即可" & CHAR(10) & CHAR(10), "3.《生财365问》" & CHAR(10), "兑换码：", AI14, CHAR(10), "使用方式：https://appamvpb5mq9834.h5.xiaoeknow.com/p/t/v1/ecommerce/mkt/redeem_index")
A15: =IF('微伴数据'!A12="","",'微伴数据'!A12) | B15: =IF('微伴数据'!B12="","",'微伴数据'!B12) | C15: =IF('微伴数据'!G12="","",'微伴数据'!G12) | D15: =IF('微伴数据'!D12="","",'微伴数据'!D12) | E15: =IF('微伴数据'!CR12="","",'微伴数据'!CR12) | F15: =IF('微伴数据'!CL12="","",'微伴数据'!CL12) | G15: B | H15: 建联 | I15: =VLOOKUP(A15,'Sheet9'!A:A,1,0) | K15: =T15&CHAR(10)&U15&CHAR(10)&V15&CHAR(10)&Y15&CHAR(10)&Z15&CHAR(10)&AA15&CHAR(10)&AB15&CHAR(10)&AC15&CHAR(10)&AD15&CHAR(10)&AE15 | L15: =IFERROR(VLOOKUP(#REF!,'第一课直播'!D:L,9,0),IFERROR(VLOOKUP('第一课回放'!C:H,5,0),"未到课")) | M15: =IFERROR(VLOOKUP(#REF!,'第一课回放'!C:H,5,0),"0:00:00") | N15: =IFERROR(VLOOKUP(#REF!,'第二课直播'!D:L,9,0),"未到课") | S15: =IFERROR(VLOOKUP(A15,'微伴数据'!A:DB,12,0),"") | T15: =IFERROR(VLOOKUP(A15,'微伴数据'!A:DB,32,0),"") | U15: =IFERROR(VLOOKUP(A15,'微伴数据'!A:DC,81,0),"") | V15: =IFERROR(VLOOKUP(#REF!,'星橙地址'!A:V,9,0),"") | W15: =IFERROR(VLOOKUP(#REF!,'星橙地址'!A:V,10,0),"") | X15: =IFERROR(VLOOKUP(A15,'星云问卷'!A:O,8,0),"") | Y15: =IFERROR(VLOOKUP(A15,'星云问卷'!A:O,9,0),"") | Z15: =IFERROR(VLOOKUP(A15,'星云问卷'!A:O,10,0),"") | AA15: =IFERROR(VLOOKUP(A15,'星云问卷'!A:O,11,0),"") | AB15: =IFERROR(VLOOKUP(A15,'星云问卷'!A:O,12,0),"") | AC15: =IFERROR(VLOOKUP(A15,'星云问卷'!A:O,13,0),"") | AD15: =IFERROR(VLOOKUP(A15,'星云问卷'!A:O,14,0),"") | AE15: =IFERROR(VLOOKUP(A15,'星云问卷'!A:O,15,0),"") | AF15: =IFERROR(VLOOKUP(A15,'微伴数据'!A:DB,72,0),"") | AG15: 54Ax8QZg | AH15: https://xiaobot.net/invitation/46210-58465-12569-7f754/ | AI15: 6dqvWpDN | AL15: =CONCATENATE( " 我把体验营用户专属福利给你发一下哈：" & CHAR(10) & CHAR(10), "1.《抖音商业IP课》" & CHAR(10), "兑换码：", AG15, CHAR(10), "兑换码使用地址：https://appamvpb5mq9834.h5.xiaoeknow.com/p/t/v1/ecommerce/mkt/redeem_index" & CHAR(10) & CHAR(10), "2.《生财有术66个项目精选》" & CHAR(10), "兑换码：", AH15, CHAR(10), "使用方式：微信搜索小报童投递-点击开始阅读-点击生财有术项目精选即可" & CHAR(10) & CHAR(10), "3.《生财365问》" & CHAR(10), "兑换码：", AI15, CHAR(10), "使用方式：https://appamvpb5mq9834.h5.xiaoeknow.com/p/t/v1/ecommerce/mkt/redeem_index")
A16: =IF('微伴数据'!A13="","",'微伴数据'!A13) | B16: =IF('微伴数据'!B13="","",'微伴数据'!B13) | C16: =IF('微伴数据'!G13="","",'微伴数据'!G13) | D16: =IF('微伴数据'!D13="","",'微伴数据'!D13) | E16: =IF('微伴数据'!CR13="","",'微伴数据'!CR13) | F16: =IF('微伴数据'!CL13="","",'微伴数据'!CL13) | G16: B | H16: 建联 | I16: =VLOOKUP(A16,'Sheet9'!A:A,1,0) | K16: =T16&CHAR(10)&U16&CHAR(10)&V16&CHAR(10)&Y16&CHAR(10)&Z16&CHAR(10)&AA16&CHAR(10)&AB16&CHAR(10)&AC16&CHAR(10)&AD16&CHAR(10)&AE16 | L16: =IFERROR(VLOOKUP(#REF!,'第一课直播'!D:L,9,0),IFERROR(VLOOKUP('第一课回放'!C:H,5,0),"未到课")) | M16: =IFERROR(VLOOKUP(#REF!,'第一课回放'!C:H,5,0),"0:00:00") | N16: =IFERROR(VLOOKUP(#REF!,'第二课直播'!D:L,9,0),"未到课") | S16: =IFERROR(VLOOKUP(A16,'微伴数据'!A:DB,12,0),"") | T16: =IFERROR(VLOOKUP(A16,'微伴数据'!A:DB,32,0),"") | U16: =IFERROR(VLOOKUP(A16,'微伴数据'!A:DC,81,0),"") | V16: =IFERROR(VLOOKUP(#REF!,'星橙地址'!A:V,9,0),"") | W16: =IFERROR(VLOOKUP(#REF!,'星橙地址'!A:V,10,0),"") | X16: =IFERROR(VLOOKUP(A16,'星云问卷'!A:O,8,0),"") | Y16: =IFERROR(VLOOKUP(A16,'星云问卷'!A:O,9,0),"") | Z16: =IFERROR(VLOOKUP(A16,'星云问卷'!A:O,10,0),"") | AA16: =IFERROR(VLOOKUP(A16,'星云问卷'!A:O,11,0),"") | AB16: =IFERROR(VLOOKUP(A16,'星云问卷'!A:O,12,0),"") | AC16: =IFERROR(VLOOKUP(A16,'星云问卷'!A:O,13,0),"") | AD16: =IFERROR(VLOOKUP(A16,'星云问卷'!A:O,14,0),"") | AE16: =IFERROR(VLOOKUP(A16,'星云问卷'!A:O,15,0),"") | AF16: =IFERROR(VLOOKUP(A16,'微伴数据'!A:DB,72,0),"") | AG16: 547pkdFq | AH16: https://xiaobot.net/invitation/5e40f-70ae2-40ca9-98f6b/ | AI16: 6dhYjFah | AL16: =CONCATENATE( " 我把体验营用户专属福利给你发一下哈：" & CHAR(10) & CHAR(10), "1.《抖音商业IP课》" & CHAR(10), "兑换码：", AG16, CHAR(10), "兑换码使用地址：https://appamvpb5mq9834.h5.xiaoeknow.com/p/t/v1/ecommerce/mkt/redeem_index" & CHAR(10) & CHAR(10), "2.《生财有术66个项目精选》" & CHAR(10), "兑换码：", AH16, CHAR(10), "使用方式：微信搜索小报童投递-点击开始阅读-点击生财有术项目精选即可" & CHAR(10) & CHAR(10), "3.《生财365问》" & CHAR(10), "兑换码：", AI16, CHAR(10), "使用方式：https://appamvpb5mq9834.h5.xiaoeknow.com/p/t/v1/ecommerce/mkt/redeem_index")
A17: =IF('微伴数据'!A14="","",'微伴数据'!A14) | B17: =IF('微伴数据'!B14="","",'微伴数据'!B14) | C17: =IF('微伴数据'!G14="","",'微伴数据'!G14) | D17: =IF('微伴数据'!D14="","",'微伴数据'!D14) | E17: =IF('微伴数据'!CR14="","",'微伴数据'!CR14) | F17: =IF('微伴数据'!CL14="","",'微伴数据'!CL14) | G17: B | H17: 建联 | I17: =VLOOKUP(A17,'Sheet9'!A:A,1,0) | K17: =T17&CHAR(10)&U17&CHAR(10)&V17&CHAR(10)&Y17&CHAR(10)&Z17&CHAR(10)&AA17&CHAR(10)&AB17&CHAR(10)&AC17&CHAR(10)&AD17&CHAR(10)&AE17 | L17: =IFERROR(VLOOKUP(#REF!,'第一课直播'!D:L,9,0),IFERROR(VLOOKUP('第一课回放'!C:H,5,0),"未到课")) | M17: =IFERROR(VLOOKUP(#REF!,'第一课回放'!C:H,5,0),"0:00:00") | N17: =IFERROR(VLOOKUP(#REF!,'第二课直播'!D:L,9,0),"未到课") | S17: =IFERROR(VLOOKUP(A17,'微伴数据'!A:DB,12,0),"") | T17: =IFERROR(VLOOKUP(A17,'微伴数据'!A:DB,32,0),"") | U17: =IFERROR(VLOOKUP(A17,'微伴数据'!A:DC,81,0),"") | V17: =IFERROR(VLOOKUP(#REF!,'星橙地址'!A:V,9,0),"") | W17: =IFERROR(VLOOKUP(#REF!,'星橙地址'!A:V,10,0),"") | X17: =IFERROR(VLOOKUP(A17,'星云问卷'!A:O,8,0),"") | Y17: =IFERROR(VLOOKUP(A17,'星云问卷'!A:O,9,0),"") | Z17: =IFERROR(VLOOKUP(A17,'星云问卷'!A:O,10,0),"") | AA17: =IFERROR(VLOOKUP(A17,'星云问卷'!A:O,11,0),"") | AB17: =IFERROR(VLOOKUP(A17,'星云问卷'!A:O,12,0),"") | AC17: =IFERROR(VLOOKUP(A17,'星云问卷'!A:O,13,0),"") | AD17: =IFERROR(VLOOKUP(A17,'星云问卷'!A:O,14,0),"") | AE17: =IFERROR(VLOOKUP(A17,'星云问卷'!A:O,15,0),"") | AF17: =IFERROR(VLOOKUP(A17,'微伴数据'!A:DB,72,0),"") | AL17: =CONCATENATE( " 我把体验营用户专属福利给你发一下哈：" & CHAR(10) & CHAR(10), "1.《抖音商业IP课》" & CHAR(10), "兑换码：", AG17, CHAR(10), "兑换码使用地址：https://appamvpb5mq9834.h5.xiaoeknow.com/p/t/v1/ecommerce/mkt/redeem_index" & CHAR(10) & CHAR(10), "2.《生财有术66个项目精选》" & CHAR(10), "兑换码：", AH17, CHAR(10), "使用方式：微信搜索小报童投递-点击开始阅读-点击生财有术项目精选即可" & CHAR(10) & CHAR(10), "3.《生财365问》" & CHAR(10), "兑换码：", AI17, CHAR(10), "使用方式：https://appamvpb5mq9834.h5.xiaoeknow.com/p/t/v1/ecommerce/mkt/redeem_index")
A18: =IF('微伴数据'!A15="","",'微伴数据'!A15) | B18: =IF('微伴数据'!B15="","",'微伴数据'!B15) | C18: =IF('微伴数据'!G15="","",'微伴数据'!G15) | D18: =IF('微伴数据'!D15="","",'微伴数据'!D15) | E18: =IF('微伴数据'!CR15="","",'微伴数据'!CR15) | F18: =IF('微伴数据'!CL15="","",'微伴数据'!CL15) | G18: B | H18: 建联 | I18: =VLOOKUP(A18,'Sheet9'!A:A,1,0) | K18: =T18&CHAR(10)&U18&CHAR(10)&V18&CHAR(10)&Y18&CHAR(10)&Z18&CHAR(10)&AA18&CHAR(10)&AB18&CHAR(10)&AC18&CHAR(10)&AD18&CHAR(10)&AE18 | L18: =IFERROR(VLOOKUP(#REF!,'第一课直播'!D:L,9,0),IFERROR(VLOOKUP('第一课回放'!C:H,5,0),"未到课")) | M18: =IFERROR(VLOOKUP(#REF!,'第一课回放'!C:H,5,0),"0:00:00") | N18: =IFERROR(VLOOKUP(#REF!,'第二课直播'!D:L,9,0),"未到课") | S18: =IFERROR(VLOOKUP(A18,'微伴数据'!A:DB,12,0),"") | T18: =IFERROR(VLOOKUP(A18,'微伴数据'!A:DB,32,0),"") | U18: =IFERROR(VLOOKUP(A18,'微伴数据'!A:DC,81,0),"") | V18: =IFERROR(VLOOKUP(#REF!,'星橙地址'!A:V,9,0),"") | W18: =IFERROR(VLOOKUP(#REF!,'星橙地址'!A:V,10,0),"") | X18: =IFERROR(VLOOKUP(A18,'星云问卷'!A:O,8,0),"") | Y18: =IFERROR(VLOOKUP(A18,'星云问卷'!A:O,9,0),"") | Z18: =IFERROR(VLOOKUP(A18,'星云问卷'!A:O,10,0),"") | AA18: =IFERROR(VLOOKUP(A18,'星云问卷'!A:O,11,0),"") | AB18: =IFERROR(VLOOKUP(A18,'星云问卷'!A:O,12,0),"") | AC18: =IFERROR(VLOOKUP(A18,'星云问卷'!A:O,13,0),"") | AD18: =IFERROR(VLOOKUP(A18,'星云问卷'!A:O,14,0),"") | AE18: =IFERROR(VLOOKUP(A18,'星云问卷'!A:O,15,0),"") | AF18: =IFERROR(VLOOKUP(A18,'微伴数据'!A:DB,72,0),"") | AL18: =CONCATENATE( " 我把体验营用户专属福利给你发一下哈：" & CHAR(10) & CHAR(10), "1.《抖音商业IP课》" & CHAR(10), "兑换码：", AG18, CHAR(10), "兑换码使用地址：https://appamvpb5mq9834.h5.xiaoeknow.com/p/t/v1/ecommerce/mkt/redeem_index" & CHAR(10) & CHAR(10), "2.《生财有术66个项目精选》" & CHAR(10), "兑换码：", AH18, CHAR(10), "使用方式：微信搜索小报童投递-点击开始阅读-点击生财有术项目精选即可" & CHAR(10) & CHAR(10), "3.《生财365问》" & CHAR(10), "兑换码：", AI18, CHAR(10), "使用方式：https://appamvpb5mq9834.h5.xiaoeknow.com/p/t/v1/ecommerce/mkt/redeem_index")
A19: =IF('微伴数据'!A16="","",'微伴数据'!A16) | B19: =IF('微伴数据'!B16="","",'微伴数据'!B16) | C19: =IF('微伴数据'!G16="","",'微伴数据'!G16) | D19: =IF('微伴数据'!D16="","",'微伴数据'!D16) | E19: =IF('微伴数据'!CR16="","",'微伴数据'!CR16) | F19: =IF('微伴数据'!CL16="","",'微伴数据'!CL16) | G19: B | H19: 建联 | I19: =VLOOKUP(A19,'Sheet9'!A:A,1,0) | K19: =T19&CHAR(10)&U19&CHAR(10)&V19&CHAR(10)&Y19&CHAR(10)&Z19&CHAR(10)&AA19&CHAR(10)&AB19&CHAR(10)&AC19&CHAR(10)&AD19&CHAR(10)&AE19 | L19: =IFERROR(VLOOKUP(#REF!,'第一课直播'!D:L,9,0),IFERROR(VLOOKUP('第一课回放'!C:H,5,0),"未到课")) | M19: =IFERROR(VLOOKUP(#REF!,'第一课回放'!C:H,5,0),"0:00:00") | N19: =IFERROR(VLOOKUP(#REF!,'第二课直播'!D:L,9,0),"未到课") | S19: =IFERROR(VLOOKUP(A19,'微伴数据'!A:DB,12,0),"") | T19: =IFERROR(VLOOKUP(A19,'微伴数据'!A:DB,32,0),"") | U19: =IFERROR(VLOOKUP(A19,'微伴数据'!A:DC,81,0),"") | V19: =IFERROR(VLOOKUP(#REF!,'星橙地址'!A:V,9,0),"") | W19: =IFERROR(VLOOKUP(#REF!,'星橙地址'!A:V,10,0),"") | X19: =IFERROR(VLOOKUP(A19,'星云问卷'!A:O,8,0),"") | Y19: =IFERROR(VLOOKUP(A19,'星云问卷'!A:O,9,0),"") | Z19: =IFERROR(VLOOKUP(A19,'星云问卷'!A:O,10,0),"") | AA19: =IFERROR(VLOOKUP(A19,'星云问卷'!A:O,11,0),"") | AB19: =IFERROR(VLOOKUP(A19,'星云问卷'!A:O,12,0),"") | AC19: =IFERROR(VLOOKUP(A19,'星云问卷'!A:O,13,0),"") | AD19: =IFERROR(VLOOKUP(A19,'星云问卷'!A:O,14,0),"") | AE19: =IFERROR(VLOOKUP(A19,'星云问卷'!A:O,15,0),"") | AF19: =IFERROR(VLOOKUP(A19,'微伴数据'!A:DB,72,0),"") | AG19: 54AkhdvV | AH19: https://xiaobot.net/invitation/11952-f5d0b-a1c7a-8bd6f/ | AI19: 6dqbDhPk | AL19: =CONCATENATE( " 我把体验营用户专属福利给你发一下哈：" & CHAR(10) & CHAR(10), "1.《抖音商业IP课》" & CHAR(10), "兑换码：", AG19, CHAR(10), "兑换码使用地址：https://appamvpb5mq9834.h5.xiaoeknow.com/p/t/v1/ecommerce/mkt/redeem_index" & CHAR(10) & CHAR(10), "2.《生财有术66个项目精选》" & CHAR(10), "兑换码：", AH19, CHAR(10), "使用方式：微信搜索小报童投递-点击开始阅读-点击生财有术项目精选即可" & CHAR(10) & CHAR(10), "3.《生财365问》" & CHAR(10), "兑换码：", AI19, CHAR(10), "使用方式：https://appamvpb5mq9834.h5.xiaoeknow.com/p/t/v1/ecommerce/mkt/redeem_index")
A20: =IF('微伴数据'!A17="","",'微伴数据'!A17) | B20: =IF('微伴数据'!B17="","",'微伴数据'!B17) | C20: =IF('微伴数据'!G17="","",'微伴数据'!G17) | D20: =IF('微伴数据'!D17="","",'微伴数据'!D17) | E20: =IF('微伴数据'!CR17="","",'微伴数据'!CR17) | F20: =IF('微伴数据'!CL17="","",'微伴数据'!CL17) | G20: B | H20: 建联 | I20: =VLOOKUP(A20,'Sheet9'!A:A,1,0) | K20: =T20&CHAR(10)&U20&CHAR(10)&V20&CHAR(10)&Y20&CHAR(10)&Z20&CHAR(10)&AA20&CHAR(10)&AB20&CHAR(10)&AC20&CHAR(10)&AD20&CHAR(10)&AE20 | L20: =IFERROR(VLOOKUP(#REF!,'第一课直播'!D:L,9,0),IFERROR(VLOOKUP('第一课回放'!C:H,5,0),"未到课")) | M20: =IFERROR(VLOOKUP(#REF!,'第一课回放'!C:H,5,0),"0:00:00") | N20: =IFERROR(VLOOKUP(#REF!,'第二课直播'!D:L,9,0),"未到课") | S20: =IFERROR(VLOOKUP(A20,'微伴数据'!A:DB,12,0),"") | T20: =IFERROR(VLOOKUP(A20,'微伴数据'!A:DB,32,0),"") | U20: 会员_7 | V20: =IFERROR(VLOOKUP(#REF!,'星橙地址'!A:V,9,0),"") | W20: =IFERROR(VLOOKUP(#REF!,'星橙地址'!A:V,10,0),"") | X20: =IFERROR(VLOOKUP(A20,'星云问卷'!A:O,8,0),"") | Y20: =IFERROR(VLOOKUP(A20,'星云问卷'!A:O,9,0),"") | Z20: =IFERROR(VLOOKUP(A20,'星云问卷'!A:O,10,0),"") | AA20: =IFERROR(VLOOKUP(A20,'星云问卷'!A:O,11,0),"") | AB20: =IFERROR(VLOOKUP(A20,'星云问卷'!A:O,12,0),"") | AC20: =IFERROR(VLOOKUP(A20,'星云问卷'!A:O,13,0),"") | AD20: =IFERROR(VLOOKUP(A20,'星云问卷'!A:O,14,0),"") | AE20: =IFERROR(VLOOKUP(A20,'星云问卷'!A:O,15,0),"") | AF20: =IFERROR(VLOOKUP(A20,'微伴数据'!A:DB,72,0),"") | AL20: =CONCATENATE( " 我把体验营用户专属福利给你发一下哈：" & CHAR(10) & CHAR(10), "1.《抖音商业IP课》" & CHAR(10), "兑换码：", AG20, CHAR(10), "兑换码使用地址：https://appamvpb5mq9834.h5.xiaoeknow.com/p/t/v1/ecommerce/mkt/redeem_index" & CHAR(10) & CHAR(10), "2.《生财有术66个项目精选》" & CHAR(10), "兑换码：", AH20, CHAR(10), "使用方式：微信搜索小报童投递-点击开始阅读-点击生财有术项目精选即可" & CHAR(10) & CHAR(10), "3.《生财365问》" & CHAR(10), "兑换码：", AI20, CHAR(10), "使用方式：https://appamvpb5mq9834.h5.xiaoeknow.com/p/t/v1/ecommerce/mkt/redeem_index") | AO20: 纳入用户画像
A21: =IF('微伴数据'!A18="","",'微伴数据'!A18) | B21: =IF('微伴数据'!B18="","",'微伴数据'!B18) | C21: =IF('微伴数据'!G18="","",'微伴数据'!G18) | D21: =IF('微伴数据'!D18="","",'微伴数据'!D18) | E21: =IF('微伴数据'!CR18="","",'微伴数据'!CR18) | F21: =IF('微伴数据'!CL18="","",'微伴数据'!CL18) | G21: S | H21: 建联 | I21: =VLOOKUP(A21,'Sheet9'!A:A,1,0) | K21: =T21&CHAR(10)&U21&CHAR(10)&V21&CHAR(10)&Y21&CHAR(10)&Z21&CHAR(10)&AA21&CHAR(10)&AB21&CHAR(10)&AC21&CHAR(10)&AD21&CHAR(10)&AE21 | L21: =IFERROR(VLOOKUP(#REF!,'第一课直播'!D:L,9,0),IFERROR(VLOOKUP('第一课回放'!C:H,5,0),"未到课")) | M21: =IFERROR(VLOOKUP(#REF!,'第一课回放'!C:H,5,0),"0:00:00") | N21: =IFERROR(VLOOKUP(#REF!,'第二课直播'!D:L,9,0),"未到课") | S21: =IFERROR(VLOOKUP(A21,'微伴数据'!A:DB,12,0),"") | T21: =IFERROR(VLOOKUP(A21,'微伴数据'!A:DB,32,0),"") | U21: =IFERROR(VLOOKUP(A21,'微伴数据'!A:DC,81,0),"") | V21: =IFERROR(VLOOKUP(#REF!,'星橙地址'!A:V,9,0),"") | W21: =IFERROR(VLOOKUP(#REF!,'星橙地址'!A:V,10,0),"") | X21: =IFERROR(VLOOKUP(A21,'星云问卷'!A:O,8,0),"") | Y21: =IFERROR(VLOOKUP(A21,'星云问卷'!A:O,9,0),"") | Z21: =IFERROR(VLOOKUP(A21,'星云问卷'!A:O,10,0),"") | AA21: =IFERROR(VLOOKUP(A21,'星云问卷'!A:O,11,0),"") | AB21: =IFERROR(VLOOKUP(A21,'星云问卷'!A:O,12,0),"") | AC21: =IFERROR(VLOOKUP(A21,'星云问卷'!A:O,13,0),"") | AD21: =IFERROR(VLOOKUP(A21,'星云问卷'!A:O,14,0),"") | AE21: =IFERROR(VLOOKUP(A21,'星云问卷'!A:O,15,0),"") | AF21: =IFERROR(VLOOKUP(A21,'微伴数据'!A:DB,72,0),"") | AL21: =CONCATENATE( " 我把体验营用户专属福利给你发一下哈：" & CHAR(10) & CHAR(10), "1.《抖音商业IP课》" & CHAR(10), "兑换码：", AG21, CHAR(10), "兑换码使用地址：https://appamvpb5mq9834.h5.xiaoeknow.com/p/t/v1/ecommerce/mkt/redeem_index" & CHAR(10) & CHAR(10), "2.《生财有术66个项目精选》" & CHAR(10), "兑换码：", AH21, CHAR(10), "使用方式：微信搜索小报童投递-点击开始阅读-点击生财有术项目精选即可" & CHAR(10) & CHAR(10), "3.《生财365问》" & CHAR(10), "兑换码：", AI21, CHAR(10), "使用方式：https://appamvpb5mq9834.h5.xiaoeknow.com/p/t/v1/ecommerce/mkt/redeem_index")
A22: =IF('微伴数据'!A19="","",'微伴数据'!A19) | B22: =IF('微伴数据'!B19="","",'微伴数据'!B19) | C22: =IF('微伴数据'!G19="","",'微伴数据'!G19) | D22: =IF('微伴数据'!D19="","",'微伴数据'!D19) | E22: =IF('微伴数据'!CR19="","",'微伴数据'!CR19) | F22: =IF('微伴数据'!CL19="","",'微伴数据'!CL19) | G22: B | H22: 建联 | I22: =VLOOKUP(A22,'Sheet9'!A:A,1,0) | K22: =T22&CHAR(10)&U22&CHAR(10)&V22&CHAR(10)&Y22&CHAR(10)&Z22&CHAR(10)&AA22&CHAR(10)&AB22&CHAR(10)&AC22&CHAR(10)&AD22&CHAR(10)&AE22 | L22: =IFERROR(VLOOKUP(#REF!,'第一课直播'!D:L,9,0),IFERROR(VLOOKUP('第一课回放'!C:H,5,0),"未到课")) | M22: =IFERROR(VLOOKUP(#REF!,'第一课回放'!C:H,5,0),"0:00:00") | N22: =IFERROR(VLOOKUP(#REF!,'第二课直播'!D:L,9,0),"未到课") | S22: =IFERROR(VLOOKUP(A22,'微伴数据'!A:DB,12,0),"") | T22: =IFERROR(VLOOKUP(A22,'微伴数据'!A:DB,32,0),"") | U22: =IFERROR(VLOOKUP(A22,'微伴数据'!A:DC,81,0),"") | V22: =IFERROR(VLOOKUP(#REF!,'星橙地址'!A:V,9,0),"") | W22: =IFERROR(VLOOKUP(#REF!,'星橙地址'!A:V,10,0),"") | X22: =IFERROR(VLOOKUP(A22,'星云问卷'!A:O,8,0),"") | Y22: =IFERROR(VLOOKUP(A22,'星云问卷'!A:O,9,0),"") | Z22: =IFERROR(VLOOKUP(A22,'星云问卷'!A:O,10,0),"") | AA22: =IFERROR(VLOOKUP(A22,'星云问卷'!A:O,11,0),"") | AB22: =IFERROR(VLOOKUP(A22,'星云问卷'!A:O,12,0),"") | AC22: =IFERROR(VLOOKUP(A22,'星云问卷'!A:O,13,0),"") | AD22: =IFERROR(VLOOKUP(A22,'星云问卷'!A:O,14,0),"") | AE22: =IFERROR(VLOOKUP(A22,'星云问卷'!A:O,15,0),"") | AF22: =IFERROR(VLOOKUP(A22,'微伴数据'!A:DB,72,0),"") | AL22: =CONCATENATE( " 我把体验营用户专属福利给你发一下哈：" & CHAR(10) & CHAR(10), "1.《抖音商业IP课》" & CHAR(10), "兑换码：", AG22, CHAR(10), "兑换码使用地址：https://appamvpb5mq9834.h5.xiaoeknow.com/p/t/v1/ecommerce/mkt/redeem_index" & CHAR(10) & CHAR(10), "2.《生财有术66个项目精选》" & CHAR(10), "兑换码：", AH22, CHAR(10), "使用方式：微信搜索小报童投递-点击开始阅读-点击生财有术项目精选即可" & CHAR(10) & CHAR(10), "3.《生财365问》" & CHAR(10), "兑换码：", AI22, CHAR(10), "使用方式：https://appamvpb5mq9834.h5.xiaoeknow.com/p/t/v1/ecommerce/mkt/redeem_index")
A23: =IF('微伴数据'!A20="","",'微伴数据'!A20) | B23: =IF('微伴数据'!B20="","",'微伴数据'!B20) | C23: =IF('微伴数据'!G20="","",'微伴数据'!G20) | D23: =IF('微伴数据'!D20="","",'微伴数据'!D20) | E23: =IF('微伴数据'!CR20="","",'微伴数据'!CR20) | F23: =IF('微伴数据'!CL20="","",'微伴数据'!CL20) | G23: B | H23: 建联 | I23: =VLOOKUP(A23,'Sheet9'!A:A,1,0) | K23: =T23&CHAR(10)&U23&CHAR(10)&V23&CHAR(10)&Y23&CHAR(10)&Z23&CHAR(10)&AA23&CHAR(10)&AB23&CHAR(10)&AC23&CHAR(10)&AD23&CHAR(10)&AE23 | L23: =IFERROR(VLOOKUP(#REF!,'第一课直播'!D:L,9,0),IFERROR(VLOOKUP('第一课回放'!C:H,5,0),"未到课")) | M23: =IFERROR(VLOOKUP(#REF!,'第一课回放'!C:H,5,0),"0:00:00") | N23: =IFERROR(VLOOKUP(#REF!,'第二课直播'!D:L,9,0),"未到课") | S23: =IFERROR(VLOOKUP(A23,'微伴数据'!A:DB,12,0),"") | T23: =IFERROR(VLOOKUP(A23,'微伴数据'!A:DB,32,0),"") | U23: =IFERROR(VLOOKUP(A23,'微伴数据'!A:DC,81,0),"") | V23: =IFERROR(VLOOKUP(#REF!,'星橙地址'!A:V,9,0),"") | W23: =IFERROR(VLOOKUP(#REF!,'星橙地址'!A:V,10,0),"") | X23: =IFERROR(VLOOKUP(A23,'星云问卷'!A:O,8,0),"") | Y23: =IFERROR(VLOOKUP(A23,'星云问卷'!A:O,9,0),"") | Z23: =IFERROR(VLOOKUP(A23,'星云问卷'!A:O,10,0),"") | AA23: =IFERROR(VLOOKUP(A23,'星云问卷'!A:O,11,0),"") | AB23: =IFERROR(VLOOKUP(A23,'星云问卷'!A:O,12,0),"") | AC23: =IFERROR(VLOOKUP(A23,'星云问卷'!A:O,13,0),"") | AD23: =IFERROR(VLOOKUP(A23,'星云问卷'!A:O,14,0),"") | AE23: =IFERROR(VLOOKUP(A23,'星云问卷'!A:O,15,0),"") | AF23: =IFERROR(VLOOKUP(A23,'微伴数据'!A:DB,72,0),"") | AL23: =CONCATENATE( " 我把体验营用户专属福利给你发一下哈：" & CHAR(10) & CHAR(10), "1.《抖音商业IP课》" & CHAR(10), "兑换码：", AG23, CHAR(10), "兑换码使用地址：https://appamvpb5mq9834.h5.xiaoeknow.com/p/t/v1/ecommerce/mkt/redeem_index" & CHAR(10) & CHAR(10), "2.《生财有术66个项目精选》" & CHAR(10), "兑换码：", AH23, CHAR(10), "使用方式：微信搜索小报童投递-点击开始阅读-点击生财有术项目精选即可" & CHAR(10) & CHAR(10), "3.《生财365问》" & CHAR(10), "兑换码：", AI23, CHAR(10), "使用方式：https://appamvpb5mq9834.h5.xiaoeknow.com/p/t/v1/ecommerce/mkt/redeem_index")
A24: =IF('微伴数据'!A21="","",'微伴数据'!A21) | B24: =IF('微伴数据'!B21="","",'微伴数据'!B21) | C24: =IF('微伴数据'!G21="","",'微伴数据'!G21) | D24: =IF('微伴数据'!D21="","",'微伴数据'!D21) | E24: =IF('微伴数据'!CR21="","",'微伴数据'!CR21) | F24: =IF('微伴数据'!CL21="","",'微伴数据'!CL21) | G24: A | H24: 建联 | I24: =VLOOKUP(A24,'Sheet9'!A:A,1,0) | K24: =T24&CHAR(10)&U24&CHAR(10)&V24&CHAR(10)&Y24&CHAR(10)&Z24&CHAR(10)&AA24&CHAR(10)&AB24&CHAR(10)&AC24&CHAR(10)&AD24&CHAR(10)&AE24 | L24: =IFERROR(VLOOKUP(#REF!,'第一课直播'!D:L,9,0),IFERROR(VLOOKUP('第一课回放'!C:H,5,0),"未到课")) | M24: =IFERROR(VLOOKUP(#REF!,'第一课回放'!C:H,5,0),"0:00:00") | N24: =IFERROR(VLOOKUP(#REF!,'第二课直播'!D:L,9,0),"未到课") | S24: =IFERROR(VLOOKUP(A24,'微伴数据'!A:DB,12,0),"") | T24: =IFERROR(VLOOKUP(A24,'微伴数据'!A:DB,32,0),"") | U24: =IFERROR(VLOOKUP(A24,'微伴数据'!A:DC,81,0),"") | V24: =IFERROR(VLOOKUP(#REF!,'星橙地址'!A:V,9,0),"") | W24: =IFERROR(VLOOKUP(#REF!,'星橙地址'!A:V,10,0),"") | X24: =IFERROR(VLOOKUP(A24,'星云问卷'!A:O,8,0),"") | Y24: =IFERROR(VLOOKUP(A24,'星云问卷'!A:O,9,0),"") | Z24: =IFERROR(VLOOKUP(A24,'星云问卷'!A:O,10,0),"") | AA24: =IFERROR(VLOOKUP(A24,'星云问卷'!A:O,11,0),"") | AB24: =IFERROR(VLOOKUP(A24,'星云问卷'!A:O,12,0),"") | AC24: =IFERROR(VLOOKUP(A24,'星云问卷'!A:O,13,0),"") | AD24: =IFERROR(VLOOKUP(A24,'星云问卷'!A:O,14,0),"") | AE24: =IFERROR(VLOOKUP(A24,'星云问卷'!A:O,15,0),"") | AF24: =IFERROR(VLOOKUP(A24,'微伴数据'!A:DB,72,0),"") | AL24: =CONCATENATE( " 我把体验营用户专属福利给你发一下哈：" & CHAR(10) & CHAR(10), "1.《抖音商业IP课》" & CHAR(10), "兑换码：", AG24, CHAR(10), "兑换码使用地址：https://appamvpb5mq9834.h5.xiaoeknow.com/p/t/v1/ecommerce/mkt/redeem_index" & CHAR(10) & CHAR(10), "2.《生财有术66个项目精选》" & CHAR(10), "兑换码：", AH24, CHAR(10), "使用方式：微信搜索小报童投递-点击开始阅读-点击生财有术项目精选即可" & CHAR(10) & CHAR(10), "3.《生财365问》" & CHAR(10), "兑换码：", AI24, CHAR(10), "使用方式：https://appamvpb5mq9834.h5.xiaoeknow.com/p/t/v1/ecommerce/mkt/redeem_index")
A25: =IF('微伴数据'!A22="","",'微伴数据'!A22) | B25: =IF('微伴数据'!B22="","",'微伴数据'!B22) | C25: =IF('微伴数据'!G22="","",'微伴数据'!G22) | D25: =IF('微伴数据'!D22="","",'微伴数据'!D22) | E25: =IF('微伴数据'!CR22="","",'微伴数据'!CR22) | F25: =IF('微伴数据'!CL22="","",'微伴数据'!CL22) | G25: B | H25: 建联 | I25: =VLOOKUP(A25,'Sheet9'!A:A,1,0) | K25: =T25&CHAR(10)&U25&CHAR(10)&V25&CHAR(10)&Y25&CHAR(10)&Z25&CHAR(10)&AA25&CHAR(10)&AB25&CHAR(10)&AC25&CHAR(10)&AD25&CHAR(10)&AE25 | L25: =IFERROR(VLOOKUP(#REF!,'第一课直播'!D:L,9,0),IFERROR(VLOOKUP('第一课回放'!C:H,5,0),"未到课")) | M25: =IFERROR(VLOOKUP(#REF!,'第一课回放'!C:H,5,0),"0:00:00") | N25: =IFERROR(VLOOKUP(#REF!,'第二课直播'!D:L,9,0),"未到课") | S25: =IFERROR(VLOOKUP(A25,'微伴数据'!A:DB,12,0),"") | T25: =IFERROR(VLOOKUP(A25,'微伴数据'!A:DB,32,0),"") | U25: =IFERROR(VLOOKUP(A25,'微伴数据'!A:DC,81,0),"") | V25: =IFERROR(VLOOKUP(#REF!,'星橙地址'!A:V,9,0),"") | W25: =IFERROR(VLOOKUP(#REF!,'星橙地址'!A:V,10,0),"") | X25: =IFERROR(VLOOKUP(A25,'星云问卷'!A:O,8,0),"") | Y25: =IFERROR(VLOOKUP(A25,'星云问卷'!A:O,9,0),"") | Z25: =IFERROR(VLOOKUP(A25,'星云问卷'!A:O,10,0),"") | AA25: =IFERROR(VLOOKUP(A25,'星云问卷'!A:O,11,0),"") | AB25: =IFERROR(VLOOKUP(A25,'星云问卷'!A:O,12,0),"") | AC25: =IFERROR(VLOOKUP(A25,'星云问卷'!A:O,13,0),"") | AD25: =IFERROR(VLOOKUP(A25,'星云问卷'!A:O,14,0),"") | AE25: =IFERROR(VLOOKUP(A25,'星云问卷'!A:O,15,0),"") | AF25: =IFERROR(VLOOKUP(A25,'微伴数据'!A:DB,72,0),"") | AL25: =CONCATENATE( " 我把体验营用户专属福利给你发一下哈：" & CHAR(10) & CHAR(10), "1.《抖音商业IP课》" & CHAR(10), "兑换码：", AG25, CHAR(10), "兑换码使用地址：https://appamvpb5mq9834.h5.xiaoeknow.com/p/t/v1/ecommerce/mkt/redeem_index" & CHAR(10) & CHAR(10), "2.《生财有术66个项目精选》" & CHAR(10), "兑换码：", AH25, CHAR(10), "使用方式：微信搜索小报童投递-点击开始阅读-点击生财有术项目精选即可" & CHAR(10) & CHAR(10), "3.《生财365问》" & CHAR(10), "兑换码：", AI25, CHAR(10), "使用方式：https://appamvpb5mq9834.h5.xiaoeknow.com/p/t/v1/ecommerce/mkt/redeem_index")
A26: =IF('微伴数据'!A23="","",'微伴数据'!A23) | B26: =IF('微伴数据'!B23="","",'微伴数据'!B23) | C26: =IF('微伴数据'!G23="","",'微伴数据'!G23) | D26: =IF('微伴数据'!D23="","",'微伴数据'!D23) | E26: =IF('微伴数据'!CR23="","",'微伴数据'!CR23) | F26: =IF('微伴数据'!CL23="","",'微伴数据'!CL23) | G26: B | H26: 建联 | I26: =VLOOKUP(A26,'Sheet9'!A:A,1,0) | K26: =T26&CHAR(10)&U26&CHAR(10)&V26&CHAR(10)&Y26&CHAR(10)&Z26&CHAR(10)&AA26&CHAR(10)&AB26&CHAR(10)&AC26&CHAR(10)&AD26&CHAR(10)&AE26 | L26: =IFERROR(VLOOKUP(#REF!,'第一课直播'!D:L,9,0),IFERROR(VLOOKUP('第一课回放'!C:H,5,0),"未到课")) | M26: =IFERROR(VLOOKUP(#REF!,'第一课回放'!C:H,5,0),"0:00:00") | N26: =IFERROR(VLOOKUP(#REF!,'第二课直播'!D:L,9,0),"未到课") | S26: =IFERROR(VLOOKUP(A26,'微伴数据'!A:DB,12,0),"") | T26: =IFERROR(VLOOKUP(A26,'微伴数据'!A:DB,32,0),"") | U26: =IFERROR(VLOOKUP(A26,'微伴数据'!A:DC,81,0),"") | V26: =IFERROR(VLOOKUP(#REF!,'星橙地址'!A:V,9,0),"") | W26: =IFERROR(VLOOKUP(#REF!,'星橙地址'!A:V,10,0),"") | X26: =IFERROR(VLOOKUP(A26,'星云问卷'!A:O,8,0),"") | Y26: =IFERROR(VLOOKUP(A26,'星云问卷'!A:O,9,0),"") | Z26: =IFERROR(VLOOKUP(A26,'星云问卷'!A:O,10,0),"") | AA26: =IFERROR(VLOOKUP(A26,'星云问卷'!A:O,11,0),"") | AB26: =IFERROR(VLOOKUP(A26,'星云问卷'!A:O,12,0),"") | AC26: =IFERROR(VLOOKUP(A26,'星云问卷'!A:O,13,0),"") | AD26: =IFERROR(VLOOKUP(A26,'星云问卷'!A:O,14,0),"") | AE26: =IFERROR(VLOOKUP(A26,'星云问卷'!A:O,15,0),"") | AF26: =IFERROR(VLOOKUP(A26,'微伴数据'!A:DB,72,0),"") | AL26: =CONCATENATE( " 我把体验营用户专属福利给你发一下哈：" & CHAR(10) & CHAR(10), "1.《抖音商业IP课》" & CHAR(10), "兑换码：", AG26, CHAR(10), "兑换码使用地址：https://appamvpb5mq9834.h5.xiaoeknow.com/p/t/v1/ecommerce/mkt/redeem_index" & CHAR(10) & CHAR(10), "2.《生财有术66个项目精选》" & CHAR(10), "兑换码：", AH26, CHAR(10), "使用方式：微信搜索小报童投递-点击开始阅读-点击生财有术项目精选即可" & CHAR(10) & CHAR(10), "3.《生财365问》" & CHAR(10), "兑换码：", AI26, CHAR(10), "使用方式：https://appamvpb5mq9834.h5.xiaoeknow.com/p/t/v1/ecommerce/mkt/redeem_index")
A27: =IF('微伴数据'!A24="","",'微伴数据'!A24) | B27: =IF('微伴数据'!B24="","",'微伴数据'!B24) | C27: =IF('微伴数据'!G24="","",'微伴数据'!G24) | D27: =IF('微伴数据'!D24="","",'微伴数据'!D24) | E27: =IF('微伴数据'!CR24="","",'微伴数据'!CR24) | F27: =IF('微伴数据'!CL24="","",'微伴数据'!CL24) | G27: B | H27: 建联 | I27: =VLOOKUP(A27,'Sheet9'!A:A,1,0) | K27: =T27&CHAR(10)&U27&CHAR(10)&V27&CHAR(10)&Y27&CHAR(10)&Z27&CHAR(10)&AA27&CHAR(10)&AB27&CHAR(10)&AC27&CHAR(10)&AD27&CHAR(10)&AE27 | L27: =IFERROR(VLOOKUP(#REF!,'第一课直播'!D:L,9,0),IFERROR(VLOOKUP('第一课回放'!C:H,5,0),"未到课")) | M27: =IFERROR(VLOOKUP(#REF!,'第一课回放'!C:H,5,0),"0:00:00") | N27: =IFERROR(VLOOKUP(#REF!,'第二课直播'!D:L,9,0),"未到课") | S27: =IFERROR(VLOOKUP(A27,'微伴数据'!A:DB,12,0),"") | T27: =IFERROR(VLOOKUP(A27,'微伴数据'!A:DB,32,0),"") | U27: =IFERROR(VLOOKUP(A27,'微伴数据'!A:DC,81,0),"") | V27: =IFERROR(VLOOKUP(#REF!,'星橙地址'!A:V,9,0),"") | W27: =IFERROR(VLOOKUP(#REF!,'星橙地址'!A:V,10,0),"") | X27: =IFERROR(VLOOKUP(A27,'星云问卷'!A:O,8,0),"") | Y27: =IFERROR(VLOOKUP(A27,'星云问卷'!A:O,9,0),"") | Z27: =IFERROR(VLOOKUP(A27,'星云问卷'!A:O,10,0),"") | AA27: =IFERROR(VLOOKUP(A27,'星云问卷'!A:O,11,0),"") | AB27: =IFERROR(VLOOKUP(A27,'星云问卷'!A:O,12,0),"") | AC27: =IFERROR(VLOOKUP(A27,'星云问卷'!A:O,13,0),"") | AD27: =IFERROR(VLOOKUP(A27,'星云问卷'!A:O,14,0),"") | AE27: =IFERROR(VLOOKUP(A27,'星云问卷'!A:O,15,0),"") | AF27: =IFERROR(VLOOKUP(A27,'微伴数据'!A:DB,72,0),"") | AG27: 547ug7e2 | AH27: https://xiaobot.net/invitation/a8a86-59098-d48bc-77bfc/ | AI27: 6dj2ZTM8 | AL27: =CONCATENATE( " 我把体验营用户专属福利给你发一下哈：" & CHAR(10) & CHAR(10), "1.《抖音商业IP课》" & CHAR(10), "兑换码：", AG27, CHAR(10), "兑换码使用地址：https://appamvpb5mq9834.h5.xiaoeknow.com/p/t/v1/ecommerce/mkt/redeem_index" & CHAR(10) & CHAR(10), "2.《生财有术66个项目精选》" & CHAR(10), "兑换码：", AH27, CHAR(10), "使用方式：微信搜索小报童投递-点击开始阅读-点击生财有术项目精选即可" & CHAR(10) & CHAR(10), "3.《生财365问》" & CHAR(10), "兑换码：", AI27, CHAR(10), "使用方式：https://appamvpb5mq9834.h5.xiaoeknow.com/p/t/v1/ecommerce/mkt/redeem_index")
A28: =IF('微伴数据'!A25="","",'微伴数据'!A25) | B28: =IF('微伴数据'!B25="","",'微伴数据'!B25) | C28: =IF('微伴数据'!G25="","",'微伴数据'!G25) | D28: =IF('微伴数据'!D25="","",'微伴数据'!D25) | E28: =IF('微伴数据'!CR25="","",'微伴数据'!CR25) | F28: =IF('微伴数据'!CL25="","",'微伴数据'!CL25) | G28: A | H28: 建联 | I28: =VLOOKUP(A28,'Sheet9'!A:A,1,0) | K28: =T28&CHAR(10)&U28&CHAR(10)&V28&CHAR(10)&Y28&CHAR(10)&Z28&CHAR(10)&AA28&CHAR(10)&AB28&CHAR(10)&AC28&CHAR(10)&AD28&CHAR(10)&AE28 | L28: =IFERROR(VLOOKUP(#REF!,'第一课直播'!D:L,9,0),IFERROR(VLOOKUP('第一课回放'!C:H,5,0),"未到课")) | M28: =IFERROR(VLOOKUP(#REF!,'第一课回放'!C:H,5,0),"0:00:00") | N28: =IFERROR(VLOOKUP(#REF!,'第二课直播'!D:L,9,0),"未到课") | S28: =IFERROR(VLOOKUP(A28,'微伴数据'!A:DB,12,0),"") | T28: =IFERROR(VLOOKUP(A28,'微伴数据'!A:DB,32,0),"") | U28: =IFERROR(VLOOKUP(A28,'微伴数据'!A:DC,81,0),"") | V28: =IFERROR(VLOOKUP(#REF!,'星橙地址'!A:V,9,0),"") | W28: =IFERROR(VLOOKUP(#REF!,'星橙地址'!A:V,10,0),"") | X28: =IFERROR(VLOOKUP(A28,'星云问卷'!A:O,8,0),"") | Y28: =IFERROR(VLOOKUP(A28,'星云问卷'!A:O,9,0),"") | Z28: =IFERROR(VLOOKUP(A28,'星云问卷'!A:O,10,0),"") | AA28: =IFERROR(VLOOKUP(A28,'星云问卷'!A:O,11,0),"") | AB28: =IFERROR(VLOOKUP(A28,'星云问卷'!A:O,12,0),"") | AC28: =IFERROR(VLOOKUP(A28,'星云问卷'!A:O,13,0),"") | AD28: =IFERROR(VLOOKUP(A28,'星云问卷'!A:O,14,0),"") | AE28: =IFERROR(VLOOKUP(A28,'星云问卷'!A:O,15,0),"") | AF28: =IFERROR(VLOOKUP(A28,'微伴数据'!A:DB,72,0),"") | AL28: =CONCATENATE( " 我把体验营用户专属福利给你发一下哈：" & CHAR(10) & CHAR(10), "1.《抖音商业IP课》" & CHAR(10), "兑换码：", AG28, CHAR(10), "兑换码使用地址：https://appamvpb5mq9834.h5.xiaoeknow.com/p/t/v1/ecommerce/mkt/redeem_index" & CHAR(10) & CHAR(10), "2.《生财有术66个项目精选》" & CHAR(10), "兑换码：", AH28, CHAR(10), "使用方式：微信搜索小报童投递-点击开始阅读-点击生财有术项目精选即可" & CHAR(10) & CHAR(10), "3.《生财365问》" & CHAR(10), "兑换码：", AI28, CHAR(10), "使用方式：https://appamvpb5mq9834.h5.xiaoeknow.com/p/t/v1/ecommerce/mkt/redeem_index")
A29: =IF('微伴数据'!A26="","",'微伴数据'!A26) | B29: =IF('微伴数据'!B26="","",'微伴数据'!B26) | C29: =IF('微伴数据'!G26="","",'微伴数据'!G26) | D29: =IF('微伴数据'!D26="","",'微伴数据'!D26) | E29: =IF('微伴数据'!CR26="","",'微伴数据'!CR26) | F29: =IF('微伴数据'!CL26="","",'微伴数据'!CL26) | G29: A | H29: 建联 | I29: =VLOOKUP(A29,'Sheet9'!A:A,1,0) | K29: =T29&CHAR(10)&U29&CHAR(10)&V29&CHAR(10)&Y29&CHAR(10)&Z29&CHAR(10)&AA29&CHAR(10)&AB29&CHAR(10)&AC29&CHAR(10)&AD29&CHAR(10)&AE29 | L29: =IFERROR(VLOOKUP(#REF!,'第一课直播'!D:L,9,0),IFERROR(VLOOKUP('第一课回放'!C:H,5,0),"未到课")) | M29: =IFERROR(VLOOKUP(#REF!,'第一课回放'!C:H,5,0),"0:00:00") | N29: =IFERROR(VLOOKUP(#REF!,'第二课直播'!D:L,9,0),"未到课") | S29: =IFERROR(VLOOKUP(A29,'微伴数据'!A:DB,12,0),"") | T29: =IFERROR(VLOOKUP(A29,'微伴数据'!A:DB,32,0),"") | U29: =IFERROR(VLOOKUP(A29,'微伴数据'!A:DC,81,0),"") | V29: =IFERROR(VLOOKUP(#REF!,'星橙地址'!A:V,9,0),"") | W29: =IFERROR(VLOOKUP(#REF!,'星橙地址'!A:V,10,0),"") | X29: =IFERROR(VLOOKUP(A29,'星云问卷'!A:O,8,0),"") | Y29: =IFERROR(VLOOKUP(A29,'星云问卷'!A:O,9,0),"") | Z29: =IFERROR(VLOOKUP(A29,'星云问卷'!A:O,10,0),"") | AA29: =IFERROR(VLOOKUP(A29,'星云问卷'!A:O,11,0),"") | AB29: =IFERROR(VLOOKUP(A29,'星云问卷'!A:O,12,0),"") | AC29: =IFERROR(VLOOKUP(A29,'星云问卷'!A:O,13,0),"") | AD29: =IFERROR(VLOOKUP(A29,'星云问卷'!A:O,14,0),"") | AE29: =IFERROR(VLOOKUP(A29,'星云问卷'!A:O,15,0),"") | AF29: =IFERROR(VLOOKUP(A29,'微伴数据'!A:DB,72,0),"") | AL29: =CONCATENATE( " 我把体验营用户专属福利给你发一下哈：" & CHAR(10) & CHAR(10), "1.《抖音商业IP课》" & CHAR(10), "兑换码：", AG29, CHAR(10), "兑换码使用地址：https://appamvpb5mq9834.h5.xiaoeknow.com/p/t/v1/ecommerce/mkt/redeem_index" & CHAR(10) & CHAR(10), "2.《生财有术66个项目精选》" & CHAR(10), "兑换码：", AH29, CHAR(10), "使用方式：微信搜索小报童投递-点击开始阅读-点击生财有术项目精选即可" & CHAR(10) & CHAR(10), "3.《生财365问》" & CHAR(10), "兑换码：", AI29, CHAR(10), "使用方式：https://appamvpb5mq9834.h5.xiaoeknow.com/p/t/v1/ecommerce/mkt/redeem_index")
A30: =IF('微伴数据'!A27="","",'微伴数据'!A27) | B30: =IF('微伴数据'!B27="","",'微伴数据'!B27) | C30: =IF('微伴数据'!G27="","",'微伴数据'!G27) | D30: =IF('微伴数据'!D27="","",'微伴数据'!D27) | E30: =IF('微伴数据'!CR27="","",'微伴数据'!CR27) | F30: =IF('微伴数据'!CL27="","",'微伴数据'!CL27) | G30: B | H30: 建联 | I30: =VLOOKUP(A30,'Sheet9'!A:A,1,0) | K30: =T30&CHAR(10)&U30&CHAR(10)&V30&CHAR(10)&Y30&CHAR(10)&Z30&CHAR(10)&AA30&CHAR(10)&AB30&CHAR(10)&AC30&CHAR(10)&AD30&CHAR(10)&AE30 | L30: =IFERROR(VLOOKUP(#REF!,'第一课直播'!D:L,9,0),IFERROR(VLOOKUP('第一课回放'!C:H,5,0),"未到课")) | M30: =IFERROR(VLOOKUP(#REF!,'第一课回放'!C:H,5,0),"0:00:00") | N30: =IFERROR(VLOOKUP(#REF!,'第二课直播'!D:L,9,0),"未到课") | S30: =IFERROR(VLOOKUP(A30,'微伴数据'!A:DB,12,0),"") | T30: =IFERROR(VLOOKUP(A30,'微伴数据'!A:DB,32,0),"") | U30: =IFERROR(VLOOKUP(A30,'微伴数据'!A:DC,81,0),"") | V30: =IFERROR(VLOOKUP(#REF!,'星橙地址'!A:V,9,0),"") | W30: =IFERROR(VLOOKUP(#REF!,'星橙地址'!A:V,10,0),"") | X30: =IFERROR(VLOOKUP(A30,'星云问卷'!A:O,8,0),"") | Y30: =IFERROR(VLOOKUP(A30,'星云问卷'!A:O,9,0),"") | Z30: =IFERROR(VLOOKUP(A30,'星云问卷'!A:O,10,0),"") | AA30: =IFERROR(VLOOKUP(A30,'星云问卷'!A:O,11,0),"") | AB30: =IFERROR(VLOOKUP(A30,'星云问卷'!A:O,12,0),"") | AC30: =IFERROR(VLOOKUP(A30,'星云问卷'!A:O,13,0),"") | AD30: =IFERROR(VLOOKUP(A30,'星云问卷'!A:O,14,0),"") | AE30: =IFERROR(VLOOKUP(A30,'星云问卷'!A:O,15,0),"") | AF30: =IFERROR(VLOOKUP(A30,'微伴数据'!A:DB,72,0),"") | AL30: =CONCATENATE( " 我把体验营用户专属福利给你发一下哈：" & CHAR(10) & CHAR(10), "1.《抖音商业IP课》" & CHAR(10), "兑换码：", AG30, CHAR(10), "兑换码使用地址：https://appamvpb5mq9834.h5.xiaoeknow.com/p/t/v1/ecommerce/mkt/redeem_index" & CHAR(10) & CHAR(10), "2.《生财有术66个项目精选》" & CHAR(10), "兑换码：", AH30, CHAR(10), "使用方式：微信搜索小报童投递-点击开始阅读-点击生财有术项目精选即可" & CHAR(10) & CHAR(10), "3.《生财365问》" & CHAR(10), "兑换码：", AI30, CHAR(10), "使用方式：https://appamvpb5mq9834.h5.xiaoeknow.com/p/t/v1/ecommerce/mkt/redeem_index")
A31: =IF('微伴数据'!A28="","",'微伴数据'!A28) | B31: =IF('微伴数据'!B28="","",'微伴数据'!B28) | C31: =IF('微伴数据'!G28="","",'微伴数据'!G28) | D31: =IF('微伴数据'!D28="","",'微伴数据'!D28) | E31: =IF('微伴数据'!CR28="","",'微伴数据'!CR28) | F31: =IF('微伴数据'!CL28="","",'微伴数据'!CL28) | G31: B | H31: 建联 | I31: =VLOOKUP(A31,'Sheet9'!A:A,1,0) | K31: =T31&CHAR(10)&U31&CHAR(10)&V31&CHAR(10)&Y31&CHAR(10)&Z31&CHAR(10)&AA31&CHAR(10)&AB31&CHAR(10)&AC31&CHAR(10)&AD31&CHAR(10)&AE31 | L31: =IFERROR(VLOOKUP(#REF!,'第一课直播'!D:L,9,0),IFERROR(VLOOKUP('第一课回放'!C:H,5,0),"未到课")) | M31: =IFERROR(VLOOKUP(#REF!,'第一课回放'!C:H,5,0),"0:00:00") | N31: =IFERROR(VLOOKUP(#REF!,'第二课直播'!D:L,9,0),"未到课") | S31: =IFERROR(VLOOKUP(A31,'微伴数据'!A:DB,12,0),"") | T31: =IFERROR(VLOOKUP(A31,'微伴数据'!A:DB,32,0),"") | U31: =IFERROR(VLOOKUP(A31,'微伴数据'!A:DC,81,0),"") | V31: =IFERROR(VLOOKUP(#REF!,'星橙地址'!A:V,9,0),"") | W31: =IFERROR(VLOOKUP(#REF!,'星橙地址'!A:V,10,0),"") | X31: =IFERROR(VLOOKUP(A31,'星云问卷'!A:O,8,0),"") | Y31: =IFERROR(VLOOKUP(A31,'星云问卷'!A:O,9,0),"") | Z31: =IFERROR(VLOOKUP(A31,'星云问卷'!A:O,10,0),"") | AA31: =IFERROR(VLOOKUP(A31,'星云问卷'!A:O,11,0),"") | AB31: =IFERROR(VLOOKUP(A31,'星云问卷'!A:O,12,0),"") | AC31: =IFERROR(VLOOKUP(A31,'星云问卷'!A:O,13,0),"") | AD31: =IFERROR(VLOOKUP(A31,'星云问卷'!A:O,14,0),"") | AE31: =IFERROR(VLOOKUP(A31,'星云问卷'!A:O,15,0),"") | AF31: =IFERROR(VLOOKUP(A31,'微伴数据'!A:DB,72,0),"") | AL31: =CONCATENATE( " 我把体验营用户专属福利给你发一下哈：" & CHAR(10) & CHAR(10), "1.《抖音商业IP课》" & CHAR(10), "兑换码：", AG31, CHAR(10), "兑换码使用地址：https://appamvpb5mq9834.h5.xiaoeknow.com/p/t/v1/ecommerce/mkt/redeem_index" & CHAR(10) & CHAR(10), "2.《生财有术66个项目精选》" & CHAR(10), "兑换码：", AH31, CHAR(10), "使用方式：微信搜索小报童投递-点击开始阅读-点击生财有术项目精选即可" & CHAR(10) & CHAR(10), "3.《生财365问》" & CHAR(10), "兑换码：", AI31, CHAR(10), "使用方式：https://appamvpb5mq9834.h5.xiaoeknow.com/p/t/v1/ecommerce/mkt/redeem_index")
A32: =IF('微伴数据'!A29="","",'微伴数据'!A29) | B32: =IF('微伴数据'!B29="","",'微伴数据'!B29) | C32: =IF('微伴数据'!G29="","",'微伴数据'!G29) | D32: =IF('微伴数据'!D29="","",'微伴数据'!D29) | E32: =IF('微伴数据'!CR29="","",'微伴数据'!CR29) | F32: =IF('微伴数据'!CL29="","",'微伴数据'!CL29) | G32: B | H32: 建联 | I32: =VLOOKUP(A32,'Sheet9'!A:A,1,0) | K32: =T32&CHAR(10)&U32&CHAR(10)&V32&CHAR(10)&Y32&CHAR(10)&Z32&CHAR(10)&AA32&CHAR(10)&AB32&CHAR(10)&AC32&CHAR(10)&AD32&CHAR(10)&AE32 | L32: =IFERROR(VLOOKUP(#REF!,'第一课直播'!D:L,9,0),IFERROR(VLOOKUP('第一课回放'!C:H,5,0),"未到课")) | M32: =IFERROR(VLOOKUP(#REF!,'第一课回放'!C:H,5,0),"0:00:00") | N32: =IFERROR(VLOOKUP(#REF!,'第二课直播'!D:L,9,0),"未到课") | S32: =IFERROR(VLOOKUP(A32,'微伴数据'!A:DB,12,0),"") | T32: =IFERROR(VLOOKUP(A32,'微伴数据'!A:DB,32,0),"") | U32: =IFERROR(VLOOKUP(A32,'微伴数据'!A:DC,81,0),"") | V32: =IFERROR(VLOOKUP(#REF!,'星橙地址'!A:V,9,0),"") | W32: =IFERROR(VLOOKUP(#REF!,'星橙地址'!A:V,10,0),"") | X32: =IFERROR(VLOOKUP(A32,'星云问卷'!A:O,8,0),"") | Y32: =IFERROR(VLOOKUP(A32,'星云问卷'!A:O,9,0),"") | Z32: =IFERROR(VLOOKUP(A32,'星云问卷'!A:O,10,0),"") | AA32: =IFERROR(VLOOKUP(A32,'星云问卷'!A:O,11,0),"") | AB32: =IFERROR(VLOOKUP(A32,'星云问卷'!A:O,12,0),"") | AC32: =IFERROR(VLOOKUP(A32,'星云问卷'!A:O,13,0),"") | AD32: =IFERROR(VLOOKUP(A32,'星云问卷'!A:O,14,0),"") | AE32: =IFERROR(VLOOKUP(A32,'星云问卷'!A:O,15,0),"") | AF32: =IFERROR(VLOOKUP(A32,'微伴数据'!A:DB,72,0),"") | AH32: https://xiaobot.net/invitation/ce769-b9f3f-3088d-544df/ | AI32: 6dfrXujW | AL32: =CONCATENATE( " 我把体验营用户专属福利给你发一下哈：" & CHAR(10) & CHAR(10), "1.《抖音商业IP课》" & CHAR(10), "兑换码：", AG32, CHAR(10), "兑换码使用地址：https://appamvpb5mq9834.h5.xiaoeknow.com/p/t/v1/ecommerce/mkt/redeem_index" & CHAR(10) & CHAR(10), "2.《生财有术66个项目精选》" & CHAR(10), "兑换码：", AH32, CHAR(10), "使用方式：微信搜索小报童投递-点击开始阅读-点击生财有术项目精选即可" & CHAR(10) & CHAR(10), "3.《生财365问》" & CHAR(10), "兑换码：", AI32, CHAR(10), "使用方式：https://appamvpb5mq9834.h5.xiaoeknow.com/p/t/v1/ecommerce/mkt/redeem_index") | AO32: 纳入用户画像
A33: =IF('微伴数据'!A30="","",'微伴数据'!A30) | B33: =IF('微伴数据'!B30="","",'微伴数据'!B30) | C33: =IF('微伴数据'!G30="","",'微伴数据'!G30) | D33: =IF('微伴数据'!D30="","",'微伴数据'!D30) | E33: =IF('微伴数据'!CR30="","",'微伴数据'!CR30) | F33: =IF('微伴数据'!CL30="","",'微伴数据'!CL30) | G33: A | H33: 建联 | I33: =VLOOKUP(A33,'Sheet9'!A:A,1,0) | K33: =T33&CHAR(10)&U33&CHAR(10)&V33&CHAR(10)&Y33&CHAR(10)&Z33&CHAR(10)&AA33&CHAR(10)&AB33&CHAR(10)&AC33&CHAR(10)&AD33&CHAR(10)&AE33 | L33: =IFERROR(VLOOKUP(#REF!,'第一课直播'!D:L,9,0),IFERROR(VLOOKUP('第一课回放'!C:H,5,0),"未到课")) | M33: =IFERROR(VLOOKUP(#REF!,'第一课回放'!C:H,5,0),"0:00:00") | N33: =IFERROR(VLOOKUP(#REF!,'第二课直播'!D:L,9,0),"未到课") | S33: =IFERROR(VLOOKUP(A33,'微伴数据'!A:DB,12,0),"") | T33: =IFERROR(VLOOKUP(A33,'微伴数据'!A:DB,32,0),"") | U33: =IFERROR(VLOOKUP(A33,'微伴数据'!A:DC,81,0),"") | V33: =IFERROR(VLOOKUP(#REF!,'星橙地址'!A:V,9,0),"") | W33: =IFERROR(VLOOKUP(#REF!,'星橙地址'!A:V,10,0),"") | X33: =IFERROR(VLOOKUP(A33,'星云问卷'!A:O,8,0),"") | Y33: =IFERROR(VLOOKUP(A33,'星云问卷'!A:O,9,0),"") | Z33: =IFERROR(VLOOKUP(A33,'星云问卷'!A:O,10,0),"") | AA33: =IFERROR(VLOOKUP(A33,'星云问卷'!A:O,11,0),"") | AB33: =IFERROR(VLOOKUP(A33,'星云问卷'!A:O,12,0),"") | AC33: =IFERROR(VLOOKUP(A33,'星云问卷'!A:O,13,0),"") | AD33: =IFERROR(VLOOKUP(A33,'星云问卷'!A:O,14,0),"") | AE33: =IFERROR(VLOOKUP(A33,'星云问卷'!A:O,15,0),"") | AF33: =IFERROR(VLOOKUP(A33,'微伴数据'!A:DB,72,0),"") | AL33: =CONCATENATE( " 我把体验营用户专属福利给你发一下哈：" & CHAR(10) & CHAR(10), "1.《抖音商业IP课》" & CHAR(10), "兑换码：", AG33, CHAR(10), "兑换码使用地址：https://appamvpb5mq9834.h5.xiaoeknow.com/p/t/v1/ecommerce/mkt/redeem_index" & CHAR(10) & CHAR(10), "2.《生财有术66个项目精选》" & CHAR(10), "兑换码：", AH33, CHAR(10), "使用方式：微信搜索小报童投递-点击开始阅读-点击生财有术项目精选即可" & CHAR(10) & CHAR(10), "3.《生财365问》" & CHAR(10), "兑换码：", AI33, CHAR(10), "使用方式：https://appamvpb5mq9834.h5.xiaoeknow.com/p/t/v1/ecommerce/mkt/redeem_index")
A34: =IF('微伴数据'!A31="","",'微伴数据'!A31) | B34: =IF('微伴数据'!B31="","",'微伴数据'!B31) | C34: =IF('微伴数据'!G31="","",'微伴数据'!G31) | D34: =IF('微伴数据'!D31="","",'微伴数据'!D31) | E34: =IF('微伴数据'!CR31="","",'微伴数据'!CR31) | F34: =IF('微伴数据'!CL31="","",'微伴数据'!CL31) | G34: B | H34: 建联 | I34: =VLOOKUP(A34,'Sheet9'!A:A,1,0) | K34: =T34&CHAR(10)&U34&CHAR(10)&V34&CHAR(10)&Y34&CHAR(10)&Z34&CHAR(10)&AA34&CHAR(10)&AB34&CHAR(10)&AC34&CHAR(10)&AD34&CHAR(10)&AE34 | L34: =IFERROR(VLOOKUP(#REF!,'第一课直播'!D:L,9,0),IFERROR(VLOOKUP('第一课回放'!C:H,5,0),"未到课")) | M34: =IFERROR(VLOOKUP(#REF!,'第一课回放'!C:H,5,0),"0:00:00") | N34: =IFERROR(VLOOKUP(#REF!,'第二课直播'!D:L,9,0),"未到课") | S34: =IFERROR(VLOOKUP(A34,'微伴数据'!A:DB,12,0),"") | T34: =IFERROR(VLOOKUP(A34,'微伴数据'!A:DB,32,0),"") | U34: =IFERROR(VLOOKUP(A34,'微伴数据'!A:DC,81,0),"") | V34: =IFERROR(VLOOKUP(#REF!,'星橙地址'!A:V,9,0),"") | W34: =IFERROR(VLOOKUP(#REF!,'星橙地址'!A:V,10,0),"") | X34: =IFERROR(VLOOKUP(A34,'星云问卷'!A:O,8,0),"") | Y34: =IFERROR(VLOOKUP(A34,'星云问卷'!A:O,9,0),"") | Z34: =IFERROR(VLOOKUP(A34,'星云问卷'!A:O,10,0),"") | AA34: =IFERROR(VLOOKUP(A34,'星云问卷'!A:O,11,0),"") | AB34: =IFERROR(VLOOKUP(A34,'星云问卷'!A:O,12,0),"") | AC34: =IFERROR(VLOOKUP(A34,'星云问卷'!A:O,13,0),"") | AD34: =IFERROR(VLOOKUP(A34,'星云问卷'!A:O,14,0),"") | AE34: =IFERROR(VLOOKUP(A34,'星云问卷'!A:O,15,0),"") | AF34: =IFERROR(VLOOKUP(A34,'微伴数据'!A:DB,72,0),"") | AL34: =CONCATENATE( " 我把体验营用户专属福利给你发一下哈：" & CHAR(10) & CHAR(10), "1.《抖音商业IP课》" & CHAR(10), "兑换码：", AG34, CHAR(10), "兑换码使用地址：https://appamvpb5mq9834.h5.xiaoeknow.com/p/t/v1/ecommerce/mkt/redeem_index" & CHAR(10) & CHAR(10), "2.《生财有术66个项目精选》" & CHAR(10), "兑换码：", AH34, CHAR(10), "使用方式：微信搜索小报童投递-点击开始阅读-点击生财有术项目精选即可" & CHAR(10) & CHAR(10), "3.《生财365问》" & CHAR(10), "兑换码：", AI34, CHAR(10), "使用方式：https://appamvpb5mq9834.h5.xiaoeknow.com/p/t/v1/ecommerce/mkt/redeem_index")
A35: =IF('微伴数据'!A32="","",'微伴数据'!A32) | B35: =IF('微伴数据'!B32="","",'微伴数据'!B32) | C35: =IF('微伴数据'!G32="","",'微伴数据'!G32) | D35: =IF('微伴数据'!D32="","",'微伴数据'!D32) | E35: =IF('微伴数据'!CR32="","",'微伴数据'!CR32) | F35: =IF('微伴数据'!CL32="","",'微伴数据'!CL32) | G35: B | H35: 建联 | I35: =VLOOKUP(A35,'Sheet9'!A:A,1,0) | K35: =T35&CHAR(10)&U35&CHAR(10)&V35&CHAR(10)&Y35&CHAR(10)&Z35&CHAR(10)&AA35&CHAR(10)&AB35&CHAR(10)&AC35&CHAR(10)&AD35&CHAR(10)&AE35 | L35: =IFERROR(VLOOKUP(#REF!,'第一课直播'!D:L,9,0),IFERROR(VLOOKUP('第一课回放'!C:H,5,0),"未到课")) | M35: =IFERROR(VLOOKUP(#REF!,'第一课回放'!C:H,5,0),"0:00:00") | N35: =IFERROR(VLOOKUP(#REF!,'第二课直播'!D:L,9,0),"未到课") | S35: =IFERROR(VLOOKUP(A35,'微伴数据'!A:DB,12,0),"") | T35: =IFERROR(VLOOKUP(A35,'微伴数据'!A:DB,32,0),"") | U35: =IFERROR(VLOOKUP(A35,'微伴数据'!A:DC,81,0),"") | V35: =IFERROR(VLOOKUP(#REF!,'星橙地址'!A:V,9,0),"") | W35: =IFERROR(VLOOKUP(#REF!,'星橙地址'!A:V,10,0),"") | X35: =IFERROR(VLOOKUP(A35,'星云问卷'!A:O,8,0),"") | Y35: =IFERROR(VLOOKUP(A35,'星云问卷'!A:O,9,0),"") | Z35: =IFERROR(VLOOKUP(A35,'星云问卷'!A:O,10,0),"") | AA35: =IFERROR(VLOOKUP(A35,'星云问卷'!A:O,11,0),"") | AB35: =IFERROR(VLOOKUP(A35,'星云问卷'!A:O,12,0),"") | AC35: =IFERROR(VLOOKUP(A35,'星云问卷'!A:O,13,0),"") | AD35: =IFERROR(VLOOKUP(A35,'星云问卷'!A:O,14,0),"") | AE35: =IFERROR(VLOOKUP(A35,'星云问卷'!A:O,15,0),"") | AF35: =IFERROR(VLOOKUP(A35,'微伴数据'!A:DB,72,0),"") | AG35: 547WKxS6 | AH35: https://xiaobot.net/invitation/6d594-8c7c9-8ba02-f2c1d/ | AI35: 6dh4zc9X | AL35: =CONCATENATE( " 我把体验营用户专属福利给你发一下哈：" & CHAR(10) & CHAR(10), "1.《抖音商业IP课》" & CHAR(10), "兑换码：", AG35, CHAR(10), "兑换码使用地址：https://appamvpb5mq9834.h5.xiaoeknow.com/p/t/v1/ecommerce/mkt/redeem_index" & CHAR(10) & CHAR(10), "2.《生财有术66个项目精选》" & CHAR(10), "兑换码：", AH35, CHAR(10), "使用方式：微信搜索小报童投递-点击开始阅读-点击生财有术项目精选即可" & CHAR(10) & CHAR(10), "3.《生财365问》" & CHAR(10), "兑换码：", AI35, CHAR(10), "使用方式：https://appamvpb5mq9834.h5.xiaoeknow.com/p/t/v1/ecommerce/mkt/redeem_index")
